Workbook

Sheet Petróleo
A1: Produção Crude Oil Mil Barris por dia | D1: US Variação no Estoque Total de Crude Oil | F1: Arábia Saudita (Crude Oil Production) | H1: Irã (crude oil production) | J1: Iraq (crude oil production) | L1: Líbia (crude oil production) | N1: Nigéria (crude oil production) | P1: Rússia (crude oil production) | R1: Venezuela (crude oil production) | T1: China (crude oil production) | V1: Brazil (Crude Oil Productin) | X1: Opep Produção Crude Oil (Estimativa Bloomberg) mil barris por dia | Z1: Arábia Saudita Produção Crude Oil | AB1: Emirados Árabes Produção Crude Oil | AD1: Irã Produção Crude Oil | AF1: Iraq Produção Crude Oil | AH1: Líbia Produção Crude Oil | AJ1: Nigeria Pordução Crude Oil | AL1: Venezuela Produção Crude Oil | AN1: Kuwait Produção Crude Oil | AP1: China Produção de Crude Oil (NBSC) (10,000 mn ton) | AS1: Brent Preço US$/Barril
A2: CROMUS Index | D2: DOEASCRD Index | F2: DWOPSAUD Index | H2: DWOPIRAN Index | J2: DWOPIRAQ Index | L2: DWOPLIBY Index | N2: DWOPNIGE Index | P2: DWOPRUSS Index | R2: DWOPVENE Index | T2: DWOPCHIN Index | V2: DWOPBRAZ Index | X2: OPCRTOTL Index | Z2: OPCRSAUD Index | AB2: OPCRUAE Index | AD2: OPCRIRAN Index | AF2: OPCRIRAQ Index | AH2: OPCRLIBY Index | AJ2: OPCRNIGE Index | AL2: OPCRVENZ Index | AN2: OPCRKUWA Index | AP2: CHENCOIL Index | AS2: CO1 Comdty
A3: {=_xll.BDH(A2, "PX_LAST", "01/01/1950", "", "Period", "M")} -> 18294 | B3: 4933 | D3: {=_xll.BDH(D2, "PX_LAST", "01/01/1950", "", "Period", "M")} -> 30194 | E3: -2626 | F3: {=_xll.BDH(F2, "PX_LAST", "01/01/1950", "", "Period", "M")} -> 34365 | G3: 8068 | H3: {=_xll.BDH(H2, "PX_LAST", "01/01/1950", "", "Period", "M")} -> 34365 | I3: 3618 | J3: {=_xll.BDH(J2, "PX_LAST", "01/01/1950", "", "Period", "M")} -> 34365 | K3: 545 | L3: {=_xll.BDH(L2, "PX_LAST", "01/01/1950", "", "Period", "M")} -> 34365 | M3: 1370 | N3: {=_xll.BDH(N2, "PX_LAST", "01/01/1950", "", "Period", "M")} -> 34365 | O3: 2085 | P3: {=_xll.BDH(P2, "PX_LAST", "01/01/1950", "", "Period", "M")} -> 34365 | Q3: 6482 | R3: {=_xll.BDH(R2, "PX_LAST", "01/01/1950", "", "Period", "M")} -> 34365 | S3: 2564 | T3: {=_xll.BDH(T2, "PX_LAST", "01/01/1950", "", "Period", "M")} -> 34365 | U3: 2900 | V3: {=_xll.BDH(V2, "PX_LAST", "01/01/1950", "", "Period", "M")} -> 34365 | W3: 680 | X3: {=_xll.BDH(X2, "PX_LAST", "01/01/1950", "", "Period", "M")} -> 23011 | Y3: 10501 | Z3: {=_xll.BDH(Z2, "PX_LAST", "01/01/1950", "", "Period", "M")} -> 23011 | AA3: 1643 | AB3: {=_xll.BDH(AB2, "PX_LAST", "01/01/1950", "", "Period", "M")} -> 23011 | AC3: 14 | AD3: {=_xll.BDH(AD2, "PX_LAST", "01/01/1950", "", "Period", "M")} -> 23011 | AE3: 1335 | AF3: {=_xll.BDH(AF2, "PX_LAST", "01/01/1950", "", "Period", "M")} -> 23011 | AG3: 1009 | AH3: {=_xll.BDH(AH2, "PX_LAST", "01/01/1950", "", "Period", "M")} -> 23011 | AI3: 182 | AJ3: {=_xll.BDH(AJ2, "PX_LAST", "01/01/1950", "", "Period", "M")} -> 23011 | AK3: 68 | AL3: {=_xll.BDH(AL2, "PX_LAST", "01/01/1950", "", "Period", "M")} -> 23011 | AM3: 3200 | AN3: {=_xll.BDH(AN2, "PX_LAST", "01/01/1950", "", "Period", "M")} -> 23011 | AO3: 1958 | AP3: {=_xll.BDH(AP2, "PX_LAST", "01/01/1950", "", "Period", "M")} -> 36191 | AQ3: 13.63 | AR3: {=_xll.BDH(AR2, "PX_LAST", "01/01/1950", "", "Period", "M")} -> #N/A Mandatory parameter [SECURITY] cannot be empty | AS3: {=_xll.BDH(AS2, "PX_LAST", "01/01/1950", "", "Period", "M")} -> 32324 | AT3: 14.85
A4: 18322 | B4: 4969 | C4: =MONTH(D4)&YEAR(D4) -> 91982 | D4: 30224 | E4: -1065 | F4: 34393 | G4: 8061 | H4: 34393 | I4: 3568 | J4: 34393 | K4: 545 | L4: 34393 | M4: 1370 | N4: 34393 | O4: 2085 | P4: 34393 | Q4: 6232 | R4: 34393 | S4: 2564 | T4: 34393 | U4: 2920 | V4: 34393 | W4: 670 | X4: 23376 | Y4: 11407 | Z4: 23376 | AA4: 1786 | AB4: 23376 | AC4: 48 | AD4: 23376 | AE4: 1491 | AF4: 23376 | AG4: 1062 | AH4: 23376 | AI4: 442 | AJ4: 23376 | AK4: 77 | AL4: 23376 | AM4: 3248 | AN4: 23376 | AO4: 2096 | AP4: 36219 | AQ4: 12.33 | AR4: 32353 | AS4: 32353 | AT4: 15.7
A5: 18353 | B5: 4881 | C5: =MONTH(D5)&YEAR(D5) -> 101982 | D5: 30253 | E5: -1303 | F5: 34424 | G5: 8068 | H5: 34424 | I5: 3668 | J5: 34424 | K5: 545 | L5: 34424 | M5: 1370 | N5: 34424 | O5: 2038 | P5: 34424 | Q5: 6181 | R5: 34424 | S5: 2564 | T5: 34424 | U5: 2920 | V5: 34424 | W5: 670 | X5: 23742 | Y5: 12976 | Z5: 23742 | AA5: 1897 | AB5: 23742 | AC5: 187 | AD5: 23742 | AE5: 1711 | AF5: 23742 | AG5: 1255 | AH5: 23742 | AI5: 862 | AJ5: 23742 | AK5: 120 | AL5: 23742 | AM5: 3393 | AN5: 23742 | AO5: 2301 | AP5: 36250 | AQ5: 13.55 | AR5: 32386 | AS5: 32386 | AT5: 14.6
A6: 18383 | B6: 4972 | C6: =MONTH(D6)&YEAR(D6) -> 111982 | D6: 30285 | E6: -5625 | F6: 34454 | G6: 8083 | H6: 34454 | I6: 3518 | J6: 34454 | K6: 555 | L6: 34454 | M6: 1370 | N6: 34454 | O6: 1962 | P6: 34454 | Q6: 6018 | R6: 34454 | S6: 2554 | T6: 34454 | U6: 2940 | V6: 34454 | W6: 670 | X6: 24107 | Y6: 14331 | Z6: 24107 | AA6: 2205 | AB6: 24107 | AC6: 282 | AD6: 24107 | AE6: 1908 | AF6: 24107 | AG6: 1313 | AH6: 24107 | AI6: 1219 | AJ6: 24107 | AK6: 274 | AL6: 24107 | AM6: 3473 | AN6: 24107 | AO6: 2360 | AP6: 36280 | AQ6: 13.2 | AR6: 32416 | AS6: 32416 | AT6: 12.24
A7: 18414 | B7: 5147 | C7: =MONTH(D7)&YEAR(D7) -> 121982 | D7: 30316 | E7: -4911 | F7: 34485 | G7: 8063 | H7: 34485 | I7: 3568 | J7: 34485 | K7: 555 | L7: 34485 | M7: 1370 | N7: 34485 | O7: 1990 | P7: 34485 | Q7: 6158 | R7: 34485 | S7: 2574 | T7: 34485 | U7: 2940 | V7: 34485 | W7: 680 | X7: 24472 | Y7: 15763 | Z7: 24472 | AA7: 2602 | AB7: 24472 | AC7: 360 | AD7: 24472 | AE7: 2132 | AF7: 24472 | AG7: 1392 | AH7: 24472 | AI7: 1501 | AJ7: 24472 | AK7: 418 | AL7: 24472 | AM7: 3371 | AN7: 24472 | AO7: 2484 | AP7: 36311 | AQ7: 13.85 | AR7: 32447 | AS7: 32447 | AT7: 12.74
A8: 18444 | B8: 5377 | C8: =MONTH(D8)&YEAR(D8) -> 11983 | D8: 30347 | E8: 5439 | F8: 34515 | G8: 8063 | H8: 34515 | I8: 3668 | J8: 34515 | K8: 555 | L8: 34515 | M8: 1370 | N8: 34515 | O8: 1981 | P8: 34515 | Q8: 6172 | R8: 34515 | S8: 2574 | T8: 34515 | U8: 2950 | V8: 34515 | W8: 680 | X8: 24837 | Y8: 16844 | Z8: 24837 | AA8: 2805 | AB8: 24837 | AC8: 382 | AD8: 24837 | AE8: 2603 | AF8: 24837 | AG8: 1228 | AH8: 24837 | AI8: 1741 | AJ8: 24837 | AK8: 319 | AL8: 24837 | AM8: 3542 | AN8: 24837 | AO8: 2500 | AP8: 36341 | AQ8: 13.23 | AR8: 32477 | AS8: 32477 | AT8: 14.05
A9: 18475 | B9: 5486 | C9: =MONTH(D9)&YEAR(D9) -> 21983 | D9: 30375 | E9: 7412 | F9: 34546 | G9: 8073 | H9: 34546 | I9: 3568 | J9: 34546 | K9: 555 | L9: 34546 | M9: 1380 | N9: 34546 | O9: 1886 | P9: 34546 | Q9: 6069 | R9: 34546 | S9: 2595 | T9: 34546 | U9: 2940 | V9: 34546 | W9: 680 | X9: 25172 | Y9: 18781 | Z9: 25203 | AA9: 3043 | AB9: 25203 | AC9: 497 | AD9: 25203 | AE9: 2840 | AF9: 25203 | AG9: 1503 | AH9: 25203 | AI9: 2602 | AJ9: 25203 | AK9: 141 | AL9: 25203 | AM9: 3605 | AN9: 25203 | AO9: 2614 | AP9: 36372 | AQ9: 13.75 | AR9: 32507 | AS9: 32507 | AT9: 15.52
A10: 18506 | B10: 5684 | C10: =MONTH(D10)&YEAR(D10) -> 31983 | D10: 30406 | E10: 1254 | F10: 34577 | G10: 8093 | H10: 34577 | I10: 3618 | J10: 34577 | K10: 555 | L10: 34577 | M10: 1390 | N10: 34577 | O10: 1545 | P10: 34577 | Q10: 6051 | R10: 34577 | S10: 2615 | T10: 34577 | U10: 2950 | V10: 34577 | W10: 700 | X10: 25568 | Y10: 20902 | Z10: 25568 | AA10: 3216 | AB10: 25568 | AC10: 628 | AD10: 25568 | AE10: 3376 | AF10: 25568 | AG10: 1521 | AH10: 25568 | AI10: 3109 | AJ10: 25568 | AK10: 540 | AL10: 25568 | AM10: 3594 | AN10: 25568 | AO10: 2773 | AP10: 36403 | AQ10: 13.62 | AR10: 32539 | AS10: 32539 | AT10: 15.91
A11: 18536 | B11: 5890 | C11: =MONTH(D11)&YEAR(D11) -> 41983 | D11: 30435 | E11: 2168 | F11: 34607 | G11: 8153 | H11: 34607 | I11: 3668 | J11: 34607 | K11: 555 | L11: 34607 | M11: 1370 | N11: 34607 | O11: 1905 | P11: 34607 | Q11: 6014 | R11: 34607 | S11: 2615 | T11: 34607 | U11: 2910 | V11: 34607 | W11: 635 | X11: 25933 | Y11: 23409 | Z11: 25933 | AA11: 3799 | AB11: 25933 | AC11: 780 | AD11: 25933 | AE11: 3829 | AF11: 25933 | AG11: 1549 | AH11: 25933 | AI11: 3318 | AJ11: 25933 | AK11: 1083 | AL11: 25933 | AM11: 3708 | AN11: 25933 | AO11: 2990 | AP11: 36433 | AQ11: 12.87 | AR11: 32567 | AS11: 32567 | AT11: 16.4
A12: 18567 | B12: 5904 | C12: =MONTH(D12)&YEAR(D12) -> 51983 | D12: 30467 | E12: 2842 | F12: 34638 | G12: 8218 | H12: 34638 | I12: 3618 | J12: 34638 | K12: 555 | L12: 34638 | M12: 1390 | N12: 34638 | O12: 1971 | P12: 34638 | Q12: 6088 | R12: 34638 | S12: 2615 | T12: 34638 | U12: 2950 | V12: 34638 | W12: 650 | X12: 26298 | Y12: 25323 | Z12: 26298 | AA12: 4769 | AB12: 26298 | AC12: 1060 | AD12: 26298 | AE12: 4540 | AF12: 26298 | AG12: 1694 | AH12: 26298 | AI12: 2761 | AJ12: 26298 | AK12: 1531 | AL12: 26298 | AM12: 3549 | AN12: 26298 | AO12: 3197 | AP12: 36464 | AQ12: 13.4 | AR12: 32598 | AS12: 32598 | AT12: 19.58
A13: 18597 | B13: 5893 | C13: =MONTH(D13)&YEAR(D13) -> 61983 | D13: 30497 | E13: -1102 | F13: 34668 | G13: 8218 | H13: 34668 | I13: 3717 | J13: 34668 | K13: 555 | L13: 34668 | M13: 1390 | N13: 34668 | O13: 1876 | P13: 34668 | Q13: 6107 | R13: 34668 | S13: 2615 | T13: 34668 | U13: 2970 | V13: 34668 | W13: 640 | X13: 26664 | Y13: 27016 | Z13: 26664 | AA13: 6016 | AB13: 26664 | AC13: 1203 | AD13: 26664 | AE13: 5023 | AF13: 26664 | AG13: 1466 | AH13: 26664 | AI13: 2239 | AJ13: 26664 | AK13: 1816 | AL13: 26664 | AM13: 3220 | AN13: 26664 | AO13: 3283 | AP13: 36494 | AQ13: 13.35 | AR13: 32626 | AS13: 32626 | AT13: 18.62
A14: 18628 | B14: 5725 | C14: =MONTH(D14)&YEAR(D14) -> 71983 | D14: 30526 | E14: 2624 | F14: 34699 | G14: 8273 | H14: 34699 | I14: 3618 | J14: 34699 | K14: 555 | L14: 34699 | M14: 1390 | N14: 34699 | O14: 1862 | P14: 34699 | Q14: 6051 | R14: 34699 | S14: 2605 | T14: 34699 | U14: 2980 | V14: 34699 | W14: 700 | X14: 27029 | Y14: 30780 | Z14: 27029 | AA14: 7596 | AB14: 27029 | AC14: 1533 | AD14: 27029 | AE14: 5861 | AF14: 27029 | AG14: 2018 | AH14: 27029 | AI14: 2175 | AJ14: 27029 | AK14: 2054 | AL14: 27029 | AM14: 3366 | AN14: 27029 | AO14: 3020 | AP14: 36525 | AQ14: 13.59 | AR14: 32659 | AS14: 32659 | AT14: 17.64
A15: 18659 | B15: 5917 | C15: =MONTH(D15)&YEAR(D15) -> 81983 | D15: 30559 | E15: 4136 | F15: 34730 | G15: 8120 | H15: 34730 | I15: 3585 | J15: 34730 | K15: 560 | L15: 34730 | M15: 1390 | N15: 34730 | O15: 1965 | P15: 34730 | Q15: 5899 | R15: 34730 | S15: 2600 | T15: 34730 | U15: 2925 | V15: 34730 | W15: 710 | X15: 27394 | Y15: 21452 | Z15: 27394 | AA15: 8480 | AB15: 27394 | AC15: 1679 | AD15: 27394 | AE15: 6022 | AF15: 27394 | AG15: 1971 | AH15: 27394 | AI15: 1521 | AJ15: 27394 | AK15: 2255 | AL15: 27394 | AM15: 2976 | AN15: 27394 | AO15: 2546 | AP15: 36556 | AQ15: 13.783 | AR15: 32689 | AS15: 32689 | AT15: 17.51
... A307: 27545 | B307: 8379 | C307: =MONTH(D307)&YEAR(D307) -> 122007 | D307: 39447 | E307: -4056 | F307: 43616 | G307: 10102 | H307: 43616 | I307: 2960 | J307: 43616 | K307: 4725 | L307: 43616 | M307: 1235 | N307: 43616 | O307: 1873.78 | P307: 43616 | Q307: 10708.992 | R307: 43616 | S307: 805 | T307: 43616 | U307: 3870.864 | V307: 43616 | W307: 2730.969 | X307: 40999 | Y307: 31095 | Z307: 40968 | AA307: 9685 | AB307: 40968 | AC307: 2595 | AD307: 40968 | AE307: 3450 | AF307: 40968 | AG307: 2760 | AH307: 40968 | AI307: 1125 | AJ307: 40968 | AK307: 2155 | AL307: 40968 | AM307: 2310 | AN307: 40968 | AO307: 2665 | AP307: 46112 | AQ307: 19.07 | AR307: 41578 | AS307: 41578 | AT307: 108.84
A308: 27575 | B308: 8421 | C308: =MONTH(D308)&YEAR(D308) -> 12008 | D308: 39478 | E308: 3555 | F308: 43646 | G308: 10202 | H308: 43646 | I308: 2870 | J308: 43646 | K308: 4725 | L308: 43646 | M308: 1175 | N308: 43646 | O308: 1993.78 | P308: 43646 | Q308: 10755.848 | R308: 43646 | S308: 855 | T308: 43646 | U308: 3787.881 | V308: 43646 | W308: 2557.432 | X308: 41029 | Y308: 31565 | Z308: 40999 | AA308: 9705 | AB308: 40999 | AC308: 2610 | AD308: 40999 | AE308: 3385 | AF308: 40999 | AG308: 2805 | AH308: 40999 | AI308: 1250 | AJ308: 40999 | AK308: 2095 | AL308: 40999 | AM308: 2315 | AN308: 40999 | AO308: 2680 | AR308: 41607 | AS308: 41607 | AT308: 109.69
A309: 27606 | B309: 8336 | C309: =MONTH(D309)&YEAR(D309) -> 22008 | D309: 39507 | E309: -3056 | F309: 43677 | G309: 9952 | H309: 43677 | I309: 2770 | J309: 43677 | K309: 4725 | L309: 43677 | M309: 1200 | N309: 43677 | O309: 1963.78 | P309: 43677 | Q309: 10750.56 | R309: 43677 | S309: 855 | T309: 43677 | U309: 3764.077 | V309: 43677 | W309: 2774.702 | X309: 41060 | Y309: 31610 | Z309: 41029 | AA309: 9820 | AB309: 41029 | AC309: 2650 | AD309: 41029 | AE309: 3275 | AF309: 41029 | AG309: 2980 | AH309: 41029 | AI309: 1350 | AJ309: 41029 | AK309: 2135 | AL309: 41029 | AM309: 2325 | AN309: 41029 | AO309: 2720 | AR309: 41639 | AS309: 41639 | AT309: 110.8
A310: 27637 | B310: 8249 | C310: =MONTH(D310)&YEAR(D310) -> 32008 | D310: 39538 | E310: 7317 | F310: 43708 | G310: 10052 | H310: 43708 | I310: 2770 | J310: 43708 | K310: 4775 | L310: 43708 | M310: 1160 | N310: 43708 | O310: 2043.78 | P310: 43708 | Q310: 10900.069 | R310: 43708 | S310: 805 | T310: 43708 | U310: 3759.097 | V310: 43708 | W310: 2989.43 | X310: 41090 | Y310: 31538 | Z310: 41060 | AA310: 9900 | AB310: 41060 | AC310: 2630 | AD310: 41060 | AE310: 3225 | AF310: 41060 | AG310: 2935 | AH310: 41060 | AI310: 1400 | AJ310: 41060 | AK310: 2175 | AL310: 41060 | AM310: 2335 | AN310: 41060 | AO310: 2725 | AR310: 41670 | AS310: 41670 | AT310: 106.4
A311: 27667 | B311: 8280 | C311: =MONTH(D311)&YEAR(D311) -> 42008 | D311: 39568 | E311: 3848 | F311: 43738 | G311: 8702 | H311: 43738 | I311: 2770 | J311: 43738 | K311: 4675 | L311: 43738 | M311: 1255 | N311: 43738 | O311: 1993.78 | P311: 43738 | Q311: 10860.032 | R311: 43738 | S311: 705 | T311: 43738 | U311: 3747.128 | V311: 43738 | W311: 2927.275 | X311: 41121 | Y311: 31603 | Z311: 41090 | AA311: 9830 | AB311: 41090 | AC311: 2605 | AD311: 41090 | AE311: 3160 | AF311: 41090 | AG311: 2960 | AH311: 41090 | AI311: 1425 | AJ311: 41090 | AK311: 2180 | AL311: 41090 | AM311: 2335 | AN311: 41090 | AO311: 2760 | AR311: 41698 | AS311: 41698 | AT311: 109.07
A312: 27698 | B312: 8324 | C312: =MONTH(D312)&YEAR(D312) -> 52008 | D312: 39598 | E312: -4802 | F312: 43769 | G312: 10052 | H312: 43769 | I312: 2765 | J312: 43769 | K312: 4775 | L312: 43769 | M312: 1245 | N312: 43769 | O312: 1973.78 | P312: 43769 | Q312: 10835.825 | R312: 43769 | S312: 690 | T312: 43769 | U312: 3773.003 | V312: 43769 | W312: 2963.895 | X312: 41152 | Y312: 31983 | Z312: 41121 | AA312: 9900 | AB312: 41121 | AC312: 2650 | AD312: 41121 | AE312: 3100 | AF312: 41121 | AG312: 2965 | AH312: 41121 | AI312: 1600 | AJ312: 41121 | AK312: 2120 | AL312: 41121 | AM312: 2340 | AN312: 41121 | AO312: 2850 | AR312: 41729 | AS312: 41729 | AT312: 107.76
A313: 27728 | B313: 8278 | C313: =MONTH(D313)&YEAR(D313) -> 62008 | D313: 39629 | E313: -1982 | F313: 43799 | G313: 10102 | H313: 43799 | I313: 2665 | J313: 43799 | K313: 4675 | L313: 43799 | M313: 1265 | N313: 43799 | O313: 1963.78 | P313: 43799 | Q313: 10853.362 | R313: 43799 | S313: 740 | T313: 43799 | U313: 3734.96 | V313: 43799 | W313: 3090.468 | X313: 41182 | Y313: 31719 | Z313: 41152 | AA313: 9900 | AB313: 41152 | AC313: 2650 | AD313: 41152 | AE313: 2750 | AF313: 41152 | AG313: 3273 | AH313: 41152 | AI313: 1560 | AJ313: 41152 | AK313: 2150 | AL313: 41152 | AM313: 2350 | AN313: 41152 | AO313: 3000 | AR313: 41759 | AS313: 41759 | AT313: 108.07
A314: 27759 | B314: 8254 | C314: =MONTH(D314)&YEAR(D314) -> 72008 | D314: 39660 | E314: -81 | F314: 43830 | G314: 9952 | H314: 43830 | I314: 2665 | J314: 43830 | K314: 4575 | L314: 43830 | M314: 1225 | N314: 43830 | O314: 1943.78 | P314: 43830 | Q314: 10871.174 | R314: 43830 | S314: 890 | T314: 43830 | U314: 3879.93 | V314: 43830 | W314: 3106.604 | X314: 41213 | Y314: 31372 | Z314: 41182 | AA314: 9800 | AB314: 41182 | AC314: 2820 | AD314: 41182 | AE314: 2850 | AF314: 41182 | AG314: 3350 | AH314: 41182 | AI314: 1475 | AJ314: 41182 | AK314: 1960 | AL314: 41182 | AM314: 2360 | AN314: 41182 | AO314: 3000 | AR314: 41789 | AS314: 41789 | AT314: 109.41
A315: 27790 | B315: 8232 | C315: =MONTH(D315)&YEAR(D315) -> 82008 | D315: 39689 | E315: -1898 | F315: 43861 | G315: 10044 | H315: 43861 | I315: 2555 | J315: 43861 | K315: 4575 | L315: 43861 | M315: 830 | N315: 43861 | O315: 1989.338 | P315: 43861 | Q315: 10916.242 | R315: 43861 | S315: 890 | T315: 43861 | U315: 3818.367 | V315: 43861 | W315: 3168.408 | X315: 41243 | Y315: 31034 | Z315: 41213 | AA315: 9800 | AB315: 41213 | AC315: 2630 | AD315: 41213 | AE315: 2650 | AF315: 41213 | AG315: 3350 | AH315: 41213 | AI315: 1450 | AJ315: 41213 | AK315: 2090 | AL315: 41213 | AM315: 2390 | AN315: 41213 | AO315: 2800 | AR315: 41820 | AS315: 41820 | AT315: 112.36
A316: 27819 | B316: 8231 | C316: =MONTH(D316)&YEAR(D316) -> 92008 | D316: 39721 | E316: 4278 | F316: 43890 | G316: 9944 | H316: 43890 | I316: 2605 | J316: 43890 | K316: 4675 | L316: 43890 | M316: 190 | N316: 43890 | O316: 1959.338 | P316: 43890 | Q316: 10897.308 | R316: 43890 | S316: 840 | T316: 43890 | U316: 3857.71 | V316: 43890 | W316: 2971.677 | X316: 41274 | Y316: 30482 | Z316: 41243 | AA316: 9700 | AB316: 41243 | AC316: 2600 | AD316: 41243 | AE316: 2700 | AF316: 41243 | AG316: 3350 | AH316: 41243 | AI316: 1430 | AJ316: 41243 | AK316: 1910 | AL316: 41243 | AM316: 2400 | AN316: 41243 | AO316: 2800 | AR316: 41851 | AS316: 41851 | AT316: 106.02
A317: 27850 | B317: 8232 | C317: =MONTH(D317)&YEAR(D317) -> 102008 | D317: 39752 | E317: 54 | F317: 43921 | G317: 9994 | H317: 43921 | I317: 2555 | J317: 43921 | K317: 4525 | L317: 43921 | M317: 140 | N317: 43921 | O317: 1939.338 | P317: 43921 | Q317: 10893.826 | R317: 43921 | S317: 670 | T317: 43921 | U317: 3820.08 | V317: 43921 | W317: 2973.386 | X317: 41305 | Y317: 30142 | Z317: 41274 | AA317: 9200 | AB317: 41274 | AC317: 2650 | AD317: 41274 | AE317: 2660 | AF317: 41274 | AG317: 3300 | AH317: 41274 | AI317: 1430 | AJ317: 41274 | AK317: 1890 | AL317: 41274 | AM317: 2410 | AN317: 41274 | AO317: 2800 | AR317: 41880 | AS317: 41880 | AT317: 103.19
A318: 27880 | B318: 8077 | C318: =MONTH(D318)&YEAR(D318) -> 112008 | D318: 39780 | E318: -456 | F318: 43951 | G318: 11794 | H318: 43951 | I318: 2530 | J318: 43951 | K318: 4525 | L318: 43951 | M318: 125 | N318: 43951 | O318: 1889.338 | P318: 43951 | Q318: 10934.822 | R318: 43951 | S318: 620 | T318: 43951 | U318: 3834.482 | V318: 43951 | W318: 2958.364 | X318: 41333 | Y318: 30164 | Z318: 41305 | AA318: 9100 | AB318: 41305 | AC318: 2600 | AD318: 41305 | AE318: 2600 | AF318: 41305 | AG318: 3200 | AH318: 41305 | AI318: 1110 | AJ318: 41305 | AK318: 1990 | AL318: 41305 | AM318: 2405 | AN318: 41305 | AO318: 2900 | AR318: 41912 | AS318: 41912 | AT318: 94.67
A319: 27911 | B319: 8125 | C319: =MONTH(D319)&YEAR(D319) -> 122008 | D319: 39813 | E319: 549 | F319: 43982 | G319: 8744 | H319: 43982 | I319: 2530 | J319: 43982 | K319: 4242 | L319: 43982 | M319: 120 | N319: 43982 | O319: 1809.338 | P319: 43982 | Q319: 8992.708 | R319: 43982 | S319: 545 | T319: 43982 | U319: 3910.912 | V319: 43982 | W319: 2765.435 | X319: 41364 | Y319: 30294 | Z319: 41333 | AA319: 9000 | AB319: 41333 | AC319: 2650 | AD319: 41333 | AE319: 2630 | AF319: 41333 | AG319: 3100 | AH319: 41333 | AI319: 1300 | AJ319: 41333 | AK319: 2080 | AL319: 41333 | AM319: 2400 | AN319: 41333 | AO319: 2850 | AR319: 41943 | AS319: 41943 | AT319: 85.86
... A386: 29951 | B386: 8585 | C386: =MONTH(D386)&YEAR(D386) -> 72014 | D386: 41851 | E386: -3697 | F386: 46022 | G386: 10060 | H386: 46022 | I386: 4220 | J386: 46022 | K386: 4321 | L386: 46022 | M386: 1428 | N386: 46022 | O386: 1569.708 | P386: 46022 | Q386: 9976.549 | R386: 46022 | S386: 905 | T386: 46022 | U386: 4190 | V386: 46022 | W386: 4014.825 | X386: 43404 | Y386: 33140 | Z386: 43373 | AA386: 10530 | AB386: 43373 | AC386: 3040 | AD386: 43373 | AE386: 3430 | AF386: 43373 | AG386: 4660 | AH386: 43373 | AI386: 1050 | AJ386: 43373 | AK386: 1800 | AL386: 43373 | AM386: 1260 | AN386: 43373 | AO386: 2800 | AR386: 43980 | AS386: 43980 | AT386: 35.33
A387: 29982 | B387: 8509 | C387: =MONTH(D387)&YEAR(D387) -> 82014 | D387: 41880 | E387: -905 | X387: 43434 | Y387: 33150 | Z387: 43404 | AA387: 10680 | AB387: 43404 | AC387: 3120 | AD387: 43404 | AE387: 3320 | AF387: 43404 | AG387: 4660 | AH387: 43404 | AI387: 1200 | AJ387: 43404 | AK387: 1800 | AL387: 43404 | AM387: 1220 | AN387: 43404 | AO387: 2790 | AR387: 44012 | AS387: 44012 | AT387: 41.15
A388: 30010 | B388: 8702 | C388: =MONTH(D388)&YEAR(D388) -> 92014 | D388: 41912 | E388: -1363 | X388: 43465 | Y388: 32550 | Z388: 43434 | AA388: 11070 | AB388: 43434 | AC388: 3270 | AD388: 43434 | AE388: 3040 | AF388: 43434 | AG388: 4570 | AH388: 43434 | AI388: 1110 | AJ388: 43434 | AK388: 1760 | AL388: 43434 | AM388: 1230 | AN388: 43434 | AO388: 2800 | AR388: 44043 | AS388: 44043 | AT388: 43.3
A389: 30041 | B389: 8667 | C389: =MONTH(D389)&YEAR(D389) -> 102014 | D389: 41943 | E389: 460 | X389: 43496 | Y389: 31060 | Z389: 43465 | AA389: 10650 | AB389: 43465 | AC389: 3260 | AD389: 43465 | AE389: 2890 | AF389: 43465 | AG389: 4700 | AH389: 43465 | AI389: 1000 | AJ389: 43465 | AK389: 1770 | AL389: 43465 | AM389: 1220 | AN389: 43465 | AO389: 2810 | AR389: 44074 | AS389: 44074 | AT389: 45.28
A390: 30071 | B390: 8591 | C390: =MONTH(D390)&YEAR(D390) -> 112014 | D390: 41971 | E390: -3689 | X390: 43524 | Y390: 30680 | Z390: 43496 | AA390: 10200 | AB390: 43496 | AC390: 3090 | AD390: 43496 | AE390: 2740 | AF390: 43496 | AG390: 4690 | AH390: 43496 | AI390: 900 | AJ390: 43496 | AK390: 1790 | AL390: 43496 | AM390: 1230 | AN390: 43496 | AO390: 2750 | AR390: 44104 | AS390: 44104 | AT390: 40.95
A391: 30102 | B391: 8683 | C391: =MONTH(D391)&YEAR(D391) -> 122014 | D391: 42004 | E391: -1754 | X391: 43555 | Y391: 30275 | Z391: 43524 | AA391: 10100 | AB391: 43524 | AC391: 3070 | AD391: 43524 | AE391: 2740 | AF391: 43524 | AG391: 4620 | AH391: 43524 | AI391: 900 | AJ391: 43524 | AK391: 1830 | AL391: 43524 | AM391: 1070 | AN391: 43524 | AO391: 2710 | AR391: 44134 | AS391: 44134 | AT391: 37.46
A392: 30132 | B392: 8646 | C392: =MONTH(D392)&YEAR(D392) -> 12015 | D392: 42034 | E392: 6333 | X392: 43585 | Y392: 30260 | Z392: 43555 | AA392: 9820 | AB392: 43555 | AC392: 3050 | AD392: 43555 | AE392: 2710 | AF392: 43555 | AG392: 4550 | AH392: 43555 | AI392: 1100 | AJ392: 43555 | AK392: 1870 | AL392: 43555 | AM392: 830 | AN392: 43555 | AO392: 2700 | AR392: 44165 | AS392: 44165 | AT392: 47.59
A393: 30163 | B393: 8658 | C393: =MONTH(D393)&YEAR(D393) -> 22015 | D393: 42062 | E393: 10303 | X393: 43616 | Y393: 30130 | Z393: 43585 | AA393: 9790 | AB393: 43585 | AC393: 3070 | AD393: 43585 | AE393: 2550 | AF393: 43585 | AG393: 4630 | AH393: 43585 | AI393: 1190 | AJ393: 43585 | AK393: 1900 | AL393: 43585 | AM393: 840 | AN393: 43585 | AO393: 2720 | AR393: 44196 | AS393: 44196 | AT393: 51.8
A394: 30194 | B394: 8634 | C394: =MONTH(D394)&YEAR(D394) -> 32015 | D394: 42094 | E394: 4766 | X394: 43646 | Y394: 30000 | Z394: 43616 | AA394: 9830 | AB394: 43616 | AC394: 3070 | AD394: 43616 | AE394: 2380 | AF394: 43616 | AG394: 4730 | AH394: 43616 | AI394: 1150 | AJ394: 43616 | AK394: 1860 | AL394: 43616 | AM394: 780 | AN394: 43616 | AO394: 2700 | AR394: 44225 | AS394: 44225 | AT394: 55.88
A395: 30224 | B395: 8701 | C395: =MONTH(D395)&YEAR(D395) -> 42015 | D395: 42124 | E395: 1910 | X395: 43677 | Y395: 29790 | Z395: 43646 | AA395: 9820 | AB395: 43646 | AC395: 3060 | AD395: 43646 | AE395: 2280 | AF395: 43646 | AG395: 4750 | AH395: 43646 | AI395: 1150 | AJ395: 43646 | AK395: 1890 | AL395: 43646 | AM395: 770 | AN395: 43646 | AO395: 2690 | AR395: 44253 | AS395: 44253 | AT395: 66.13
A396: 30255 | B396: 8701 | C396: =MONTH(D396)&YEAR(D396) -> 52015 | D396: 42153 | E396: -1948 | X396: 43708 | Y396: 29910 | Z396: 43677 | AA396: 9780 | AB396: 43677 | AC396: 3060 | AD396: 43677 | AE396: 2210 | AF396: 43677 | AG396: 4750 | AH396: 43677 | AI396: 1100 | AJ396: 43677 | AK396: 1890 | AL396: 43677 | AM396: 780 | AN396: 43677 | AO396: 2680 | AR396: 44286 | AS396: 44286 | AT396: 63.54
A397: 30285 | B397: 8697 | C397: =MONTH(D397)&YEAR(D397) -> 62015 | D397: 42185 | E397: 2386 | X397: 43738 | Y397: 28590 | Z397: 43708 | AA397: 9830 | AB397: 43708 | AC397: 3070 | AD397: 43708 | AE397: 2210 | AF397: 43708 | AG397: 4780 | AH397: 43708 | AI397: 1070 | AJ397: 43708 | AK397: 1950 | AL397: 43708 | AM397: 760 | AN397: 43708 | AO397: 2640 | AR397: 44316 | AS397: 44316 | AT397: 67.25
...

Sheet Estoque_US
B1: Estoques de Petróleo Bruto (Semanal) | D1: Estoques de Petróleo Bruto (Mensal)
B2: DOEASCRD Index
A3: =MONTH(B3)&YEAR(B3) -> 11990 | B3: {=_xll.BDH($B$2, "PX_LAST", "01/01/1990", "")} -> 32878 | C3: 20 | D3: 32904 | E3: =SUMIF(A:A,MONTH(D3)&YEAR(D3),C:C) -> -79
A4: =MONTH(B4)&YEAR(B4) -> 11990 | B4: 32885 | C4: 3597 | D4: 32932 | E4: =SUMIF(A:A,MONTH(D4)&YEAR(D4),C:C) -> -2296
A5: =MONTH(B5)&YEAR(B5) -> 11990 | B5: 32892 | C5: -1646 | D5: 32963 | E5: =SUMIF(A:A,MONTH(D5)&YEAR(D5),C:C) -> 20780
A6: =MONTH(B6)&YEAR(B6) -> 11990 | B6: 32899 | C6: -2050 | D6: 32993 | E6: =SUMIF(A:A,MONTH(D6)&YEAR(D6),C:C) -> 10802
A7: =MONTH(B7)&YEAR(B7) -> 21990 | B7: 32906 | C7: 9539 | D7: 33024 | E7: =SUMIF(A:A,MONTH(D7)&YEAR(D7),C:C) -> 8603
A8: =MONTH(B8)&YEAR(B8) -> 21990 | B8: 32913 | C8: -4812 | D8: 33054 | E8: =SUMIF(A:A,MONTH(D8)&YEAR(D8),C:C) -> 5572
A9: =MONTH(B9)&YEAR(B9) -> 21990 | B9: 32920 | C9: -2447 | D9: 33085 | E9: =SUMIF(A:A,MONTH(D9)&YEAR(D9),C:C) -> 3735
A10: =MONTH(B10)&YEAR(B10) -> 21990 | B10: 32927 | C10: -4576 | D10: 33116 | E10: =SUMIF(A:A,MONTH(D10)&YEAR(D10),C:C) -> -16027
A11: =MONTH(B11)&YEAR(B11) -> 31990 | B11: 32934 | C11: 3731 | D11: 33146 | E11: =SUMIF(A:A,MONTH(D11)&YEAR(D11),C:C) -> -18310
A12: =MONTH(B12)&YEAR(B12) -> 31990 | B12: 32941 | C12: 6326 | D12: 33177 | E12: =SUMIF(A:A,MONTH(D12)&YEAR(D12),C:C) -> -11229
A13: =MONTH(B13)&YEAR(B13) -> 31990 | B13: 32948 | C13: -1446 | D13: 33207 | E13: =SUMIF(A:A,MONTH(D13)&YEAR(D13),C:C) -> -488
A14: =MONTH(B14)&YEAR(B14) -> 31990 | B14: 32955 | C14: 9235 | D14: 33238 | E14: =SUMIF(A:A,MONTH(D14)&YEAR(D14),C:C) -> -10990
A15: =MONTH(B15)&YEAR(B15) -> 31990 | B15: 32962 | C15: 2934 | D15: 33269 | E15: =SUMIF(A:A,MONTH(D15)&YEAR(D15),C:C) -> -8112
... A408: =MONTH(B408)&YEAR(B408) -> 101997 | B408: 35713 | C408: -2172 | D408: 45230 | E408: =SUMIF(A:A,MONTH(D408)&YEAR(D408),C:C) -> 7830
A409: =MONTH(B409)&YEAR(B409) -> 101997 | B409: 35720 | C409: -3298 | D409: =EOMONTH(D408,1) -> 45260 | E409: =SUMIF(A:A,MONTH(D409)&YEAR(D409),C:C) -> 27771
A410: =MONTH(B410)&YEAR(B410) -> 101997 | B410: 35727 | C410: 4605 | D410: =EOMONTH(D409,1) -> 45291 | E410: =SUMIF(A:A,MONTH(D410)&YEAR(D410),C:C) -> -18599
A411: =MONTH(B411)&YEAR(B411) -> 101997 | B411: 35734 | C411: 6019 | D411: =EOMONTH(D410,1) -> 45322 | E411: =SUMIF(A:A,MONTH(D411)&YEAR(D411),C:C) -> -9153
A412: =MONTH(B412)&YEAR(B412) -> 111997 | B412: 35741 | C412: -1180 | D412: =EOMONTH(D411,1) -> 45351 | E412: =SUMIF(A:A,MONTH(D412)&YEAR(D412),C:C) -> 25251
A413: =MONTH(B413)&YEAR(B413) -> 111997 | B413: 35748 | C413: 5286 | D413: =EOMONTH(D412,1) -> 45382 | E413: =SUMIF(A:A,MONTH(D413)&YEAR(D413),C:C) -> 4254
A414: =MONTH(B414)&YEAR(B414) -> 111997 | B414: 35755 | C414: 3774 | D414: =EOMONTH(D413,1) -> 45412 | E414: =SUMIF(A:A,MONTH(D414)&YEAR(D414),C:C) -> 9473
A415: =MONTH(B415)&YEAR(B415) -> 111997 | B415: 35762 | C415: 2820 | D415: =EOMONTH(D414,1) -> 45443 | E415: =SUMIF(A:A,MONTH(D415)&YEAR(D415),C:C) -> -4968
A416: =MONTH(B416)&YEAR(B416) -> 121997 | B416: 35769 | C416: -4802 | D416: =EOMONTH(D415,1) -> 45473 | E416: =SUMIF(A:A,MONTH(D416)&YEAR(D416),C:C) -> -7383
A417: =MONTH(B417)&YEAR(B417) -> 121997 | B417: 35776 | C417: 2540 | D417: =EOMONTH(D416,1) -> 45504 | E417: =SUMIF(A:A,MONTH(D417)&YEAR(D417),C:C) -> -15490
A418: =MONTH(B418)&YEAR(B418) -> 121997 | B418: 35783 | C418: -3969 | D418: =EOMONTH(D417,1) -> 45535 | E418: =SUMIF(A:A,MONTH(D418)&YEAR(D418),C:C) -> -14739
A419: =MONTH(B419)&YEAR(B419) -> 121997 | B419: 35790 | C419: -3252 | D419: =EOMONTH(D418,1) -> 45565 | E419: =SUMIF(A:A,MONTH(D419)&YEAR(D419),C:C) -> -1379
A420: =MONTH(B420)&YEAR(B420) -> 11998 | B420: 35797 | C420: -6402 | D420: =EOMONTH(D419,1) -> 45596 | E420: =SUMIF(A:A,MONTH(D420)&YEAR(D420),C:C) -> 8578
... A422: =MONTH(B422)&YEAR(B422) -> 11998 | B422: 35811 | C422: 11212 | D422: =EOMONTH(D421,1) -> 45657 | E422: =SUMIF(A:A,MONTH(D422)&YEAR(D422),C:C) -> -7774
A423: =MONTH(B423)&YEAR(B423) -> 11998 | B423: 35818 | C423: 5686 | D423: 45658 | E423: =SUMIF(A:A,MONTH(D423)&YEAR(D423),C:C) -> 8189
A424: =MONTH(B424)&YEAR(B424) -> 11998 | B424: 35825 | C424: -622 | D424: 45689 | E424: =SUMIF(A:A,MONTH(D424)&YEAR(D424),C:C) -> 9985
A425: =MONTH(B425)&YEAR(B425) -> 21998 | B425: 35832 | C425: -8 | D425: 45717 | E425: =SUMIF(A:A,MONTH(D425)&YEAR(D425),C:C) -> 6017
A426: =MONTH(B426)&YEAR(B426) -> 21998 | B426: 35839 | C426: 1702 | D426: 45748 | E426: =SUMIF(A:A,MONTH(D426)&YEAR(D426),C:C) -> 616
A427: =MONTH(B427)&YEAR(B427) -> 21998 | B427: 35846 | C427: 2883 | D427: 45778 | E427: =SUMIF(A:A,MONTH(D427)&YEAR(D427),C:C) -> -4349
A428: =MONTH(B428)&YEAR(B428) -> 21998 | B428: 35853 | C428: -1599 | D428: 45809 | E428: =SUMIF(A:A,MONTH(D428)&YEAR(D428),C:C) -> -17108
A429: =MONTH(B429)&YEAR(B429) -> 31998 | B429: 35860 | C429: -921 | D429: 45839 | E429: =SUMIF(A:A,MONTH(D429)&YEAR(D429),C:C) -> 7070
A430: =MONTH(B430)&YEAR(B430) -> 31998 | B430: 35867 | C430: -2057 | D430: 45870 | E430: =SUMIF(A:A,MONTH(D430)&YEAR(D430),C:C) -> 0
A431: =MONTH(B431)&YEAR(B431) -> 31998 | B431: 35874 | C431: 6469 | D431: 45901 | E431: =SUMIF(A:A,MONTH(D431)&YEAR(D431),C:C) -> 0
A432: =MONTH(B432)&YEAR(B432) -> 31998 | B432: 35881 | C432: 1594 | D432: 45931 | E432: =SUMIF(A:A,MONTH(D432)&YEAR(D432),C:C) -> 0
A433: =MONTH(B433)&YEAR(B433) -> 41998 | B433: 35888 | C433: 1567 | D433: 45962 | E433: =SUMIF(A:A,MONTH(D433)&YEAR(D433),C:C) -> 0
...

Sheet Eviews
C1: Doe_US_Prod | D1: Doe_US_Invent | E1: Doe_AS_prod | F1: Doe_ira_prod | G1: Doe_irq_prod | H1: Doe_lib_prod | I1: Doe_nig_prod | J1: Doe_rus_prod | K1: Doe_Ven_prod | L1: Doe_chi_prod | M1: Bbg_opep_prod | N1: Bbg_SA_prod | O1: Bbg_Ae_prod | P1: Bbg_ira_prod | Q1: Bbg_irq_prod | R1: Bbg_lib_prod | S1: Bbg_nig_prod | T1: Bbg_ven_prod | U1: Bbg_kuw_prod | V1: P_brent | X1: Doe_US_Prod
A2: =MONTH(B2)&YEAR(B2) -> 11990 | B2: 32904 | C2: =IFERROR(VLOOKUP(B2,Petróleo!A:B,2,FALSE),"") -> 7546 | D2: =IFERROR(VLOOKUP(B2,Estoque_US!D:E,2,FALSE),"") -> -79 | E2: =IFERROR(VLOOKUP(B2,Petróleo!F:G,2,FALSE),"") | F2: =IFERROR(VLOOKUP(B2,Petróleo!H:I,2,FALSE),"") | G2: =IFERROR(VLOOKUP(B2,Petróleo!J:K,2,FALSE),"") | H2: =IFERROR(VLOOKUP(B2,Petróleo!L:M,2,FALSE),"") | I2: =IFERROR(VLOOKUP(B2,Petróleo!N:O,2,FALSE),"") | J2: =IFERROR(VLOOKUP(B2,Petróleo!P:Q,2,FALSE),"") | K2: =IFERROR(VLOOKUP(B2,Petróleo!R:S,2,FALSE),"") | L2: =IFERROR(VLOOKUP(B2,Petróleo!T:U,2,FALSE),"") | M2: =IFERROR(VLOOKUP($B$2,Petróleo!X:Y,2,FALSE),"") -> 23320 | N2: =IFERROR(VLOOKUP(B2,Petróleo!Z:AA,2,FALSE),"") -> 5775 | O2: =IFERROR(VLOOKUP(B2,Petróleo!AB:AC,2,FALSE),"") -> 2000 | P2: =IFERROR(VLOOKUP(B2,Petróleo!AD:AE,2,FALSE),"") -> 2500 | Q2: =IFERROR(VLOOKUP(B2,Petróleo!AF:AG,2,FALSE),"") -> 3150 | R2: =IFERROR(VLOOKUP(B2,Petróleo!AH:AI,2,FALSE),"") -> 1350 | S2: =IFERROR(VLOOKUP(B2,Petróleo!AJ:AK,2,FALSE),"") -> 1700 | T2: =IFERROR(VLOOKUP(B2,Petróleo!AL:AM,2,FALSE),"") -> 1950 | U2: =IFERROR(VLOOKUP(B2,Petróleo!AN:AO,2,FALSE),"") -> 1975 | V2: =IFERROR(VLOOKUP(A2,Petróleo!AR:AT,3,FALSE),"") | X2: Doe_US_Invent
A3: =MONTH(B3)&YEAR(B3) -> 21990 | B3: 32932 | C3: =IFERROR(VLOOKUP(B3,Petróleo!A:B,2,FALSE),"") -> 7497 | D3: =IFERROR(VLOOKUP(B3,Estoque_US!D:E,2,FALSE),"") -> -2296 | E3: =IFERROR(VLOOKUP(B3,Petróleo!F:G,2,FALSE),"") | F3: =IFERROR(VLOOKUP(B3,Petróleo!H:I,2,FALSE),"") | G3: =IFERROR(VLOOKUP(B3,Petróleo!J:K,2,FALSE),"") | H3: =IFERROR(VLOOKUP(B3,Petróleo!L:M,2,FALSE),"") | I3: =IFERROR(VLOOKUP(B3,Petróleo!N:O,2,FALSE),"") | J3: =IFERROR(VLOOKUP(B3,Petróleo!P:Q,2,FALSE),"") | K3: =IFERROR(VLOOKUP(B3,Petróleo!R:S,2,FALSE),"") | L3: =IFERROR(VLOOKUP(B3,Petróleo!T:U,2,FALSE),"") | M3: =IFERROR(VLOOKUP(B3,Petróleo!X:Y,2,FALSE),"") -> 23120 | N3: =IFERROR(VLOOKUP(B3,Petróleo!Z:AA,2,FALSE),"") -> 5625 | O3: =IFERROR(VLOOKUP(B3,Petróleo!AB:AC,2,FALSE),"") -> 2000 | P3: =IFERROR(VLOOKUP(B3,Petróleo!AD:AE,2,FALSE),"") -> 2300 | Q3: =IFERROR(VLOOKUP(B3,Petróleo!AF:AG,2,FALSE),"") -> 3100 | R3: =IFERROR(VLOOKUP(B3,Petróleo!AH:AI,2,FALSE),"") -> 1350 | S3: =IFERROR(VLOOKUP(B3,Petróleo!AJ:AK,2,FALSE),"") -> 1800 | T3: =IFERROR(VLOOKUP(B3,Petróleo!AL:AM,2,FALSE),"") -> 2050 | U3: =IFERROR(VLOOKUP(B3,Petróleo!AN:AO,2,FALSE),"") -> 1975 | V3: =IFERROR(VLOOKUP(A3,Petróleo!AR:AT,3,FALSE),"") | X3: Doe_AS_prod
A4: =MONTH(B4)&YEAR(B4) -> 31990 | B4: 32963 | C4: =IFERROR(VLOOKUP(B4,Petróleo!A:B,2,FALSE),"") -> 7433 | D4: =IFERROR(VLOOKUP(B4,Estoque_US!D:E,2,FALSE),"") -> 20780 | E4: =IFERROR(VLOOKUP(B4,Petróleo!F:G,2,FALSE),"") | F4: =IFERROR(VLOOKUP(B4,Petróleo!H:I,2,FALSE),"") | G4: =IFERROR(VLOOKUP(B4,Petróleo!J:K,2,FALSE),"") | H4: =IFERROR(VLOOKUP(B4,Petróleo!L:M,2,FALSE),"") | I4: =IFERROR(VLOOKUP(B4,Petróleo!N:O,2,FALSE),"") | J4: =IFERROR(VLOOKUP(B4,Petróleo!P:Q,2,FALSE),"") | K4: =IFERROR(VLOOKUP(B4,Petróleo!R:S,2,FALSE),"") | L4: =IFERROR(VLOOKUP(B4,Petróleo!T:U,2,FALSE),"") | M4: =IFERROR(VLOOKUP(B4,Petróleo!X:Y,2,FALSE),"") -> 24090 | N4: =IFERROR(VLOOKUP(B4,Petróleo!Z:AA,2,FALSE),"") -> 5675 | O4: =IFERROR(VLOOKUP(B4,Petróleo!AB:AC,2,FALSE),"") -> 2000 | P4: =IFERROR(VLOOKUP(B4,Petróleo!AD:AE,2,FALSE),"") -> 3150 | Q4: =IFERROR(VLOOKUP(B4,Petróleo!AF:AG,2,FALSE),"") -> 3100 | R4: =IFERROR(VLOOKUP(B4,Petróleo!AH:AI,2,FALSE),"") -> 1350 | S4: =IFERROR(VLOOKUP(B4,Petróleo!AJ:AK,2,FALSE),"") -> 1850 | T4: =IFERROR(VLOOKUP(B4,Petróleo!AL:AM,2,FALSE),"") -> 1950 | U4: =IFERROR(VLOOKUP(B4,Petróleo!AN:AO,2,FALSE),"") -> 2075 | V4: =IFERROR(VLOOKUP(A4,Petróleo!AR:AT,3,FALSE),"") | X4: Doe_ira_prod
A5: =MONTH(B5)&YEAR(B5) -> 41990 | B5: 32993 | C5: =IFERROR(VLOOKUP(B5,Petróleo!A:B,2,FALSE),"") -> 7407 | D5: =IFERROR(VLOOKUP(B5,Estoque_US!D:E,2,FALSE),"") -> 10802 | E5: =IFERROR(VLOOKUP(B5,Petróleo!F:G,2,FALSE),"") | F5: =IFERROR(VLOOKUP(B5,Petróleo!H:I,2,FALSE),"") | G5: =IFERROR(VLOOKUP(B5,Petróleo!J:K,2,FALSE),"") | H5: =IFERROR(VLOOKUP(B5,Petróleo!L:M,2,FALSE),"") | I5: =IFERROR(VLOOKUP(B5,Petróleo!N:O,2,FALSE),"") | J5: =IFERROR(VLOOKUP(B5,Petróleo!P:Q,2,FALSE),"") | K5: =IFERROR(VLOOKUP(B5,Petróleo!R:S,2,FALSE),"") | L5: =IFERROR(VLOOKUP(B5,Petróleo!T:U,2,FALSE),"") | M5: =IFERROR(VLOOKUP(B5,Petróleo!X:Y,2,FALSE),"") -> 23980 | N5: =IFERROR(VLOOKUP(B5,Petróleo!Z:AA,2,FALSE),"") -> 5850 | O5: =IFERROR(VLOOKUP(B5,Petróleo!AB:AC,2,FALSE),"") -> 2100 | P5: =IFERROR(VLOOKUP(B5,Petróleo!AD:AE,2,FALSE),"") -> 3010 | Q5: =IFERROR(VLOOKUP(B5,Petróleo!AF:AG,2,FALSE),"") -> 3050 | R5: =IFERROR(VLOOKUP(B5,Petróleo!AH:AI,2,FALSE),"") -> 1300 | S5: =IFERROR(VLOOKUP(B5,Petróleo!AJ:AK,2,FALSE),"") -> 1800 | T5: =IFERROR(VLOOKUP(B5,Petróleo!AL:AM,2,FALSE),"") -> 2000 | U5: =IFERROR(VLOOKUP(B5,Petróleo!AN:AO,2,FALSE),"") -> 1900 | V5: =IFERROR(VLOOKUP(A5,Petróleo!AR:AT,3,FALSE),"") | X5: Doe_irq_prod
A6: =MONTH(B6)&YEAR(B6) -> 51990 | B6: 33024 | C6: =IFERROR(VLOOKUP(B6,Petróleo!A:B,2,FALSE),"") -> 7328 | D6: =IFERROR(VLOOKUP(B6,Estoque_US!D:E,2,FALSE),"") -> 8603 | E6: =IFERROR(VLOOKUP(B6,Petróleo!F:G,2,FALSE),"") | F6: =IFERROR(VLOOKUP(B6,Petróleo!H:I,2,FALSE),"") | G6: =IFERROR(VLOOKUP(B6,Petróleo!J:K,2,FALSE),"") | H6: =IFERROR(VLOOKUP(B6,Petróleo!L:M,2,FALSE),"") | I6: =IFERROR(VLOOKUP(B6,Petróleo!N:O,2,FALSE),"") | J6: =IFERROR(VLOOKUP(B6,Petróleo!P:Q,2,FALSE),"") | K6: =IFERROR(VLOOKUP(B6,Petróleo!R:S,2,FALSE),"") | L6: =IFERROR(VLOOKUP(B6,Petróleo!T:U,2,FALSE),"") | M6: =IFERROR(VLOOKUP(B6,Petróleo!X:Y,2,FALSE),"") -> 23680 | N6: =IFERROR(VLOOKUP(B6,Petróleo!Z:AA,2,FALSE),"") -> 5250 | O6: =IFERROR(VLOOKUP(B6,Petróleo!AB:AC,2,FALSE),"") -> 2050 | P6: =IFERROR(VLOOKUP(B6,Petróleo!AD:AE,2,FALSE),"") -> 3430 | Q6: =IFERROR(VLOOKUP(B6,Petróleo!AF:AG,2,FALSE),"") -> 3150 | R6: =IFERROR(VLOOKUP(B6,Petróleo!AH:AI,2,FALSE),"") -> 1300 | S6: =IFERROR(VLOOKUP(B6,Petróleo!AJ:AK,2,FALSE),"") -> 1700 | T6: =IFERROR(VLOOKUP(B6,Petróleo!AL:AM,2,FALSE),"") -> 2000 | U6: =IFERROR(VLOOKUP(B6,Petróleo!AN:AO,2,FALSE),"") -> 1900 | V6: =IFERROR(VLOOKUP(A6,Petróleo!AR:AT,3,FALSE),"") | X6: Doe_lib_prod
A7: =MONTH(B7)&YEAR(B7) -> 61990 | B7: 33054 | C7: =IFERROR(VLOOKUP(B7,Petróleo!A:B,2,FALSE),"") -> 7106 | D7: =IFERROR(VLOOKUP(B7,Estoque_US!D:E,2,FALSE),"") -> 5572 | E7: =IFERROR(VLOOKUP(B7,Petróleo!F:G,2,FALSE),"") | F7: =IFERROR(VLOOKUP(B7,Petróleo!H:I,2,FALSE),"") | G7: =IFERROR(VLOOKUP(B7,Petróleo!J:K,2,FALSE),"") | H7: =IFERROR(VLOOKUP(B7,Petróleo!L:M,2,FALSE),"") | I7: =IFERROR(VLOOKUP(B7,Petróleo!N:O,2,FALSE),"") | J7: =IFERROR(VLOOKUP(B7,Petróleo!P:Q,2,FALSE),"") | K7: =IFERROR(VLOOKUP(B7,Petróleo!R:S,2,FALSE),"") | L7: =IFERROR(VLOOKUP(B7,Petróleo!T:U,2,FALSE),"") | M7: =IFERROR(VLOOKUP(B7,Petróleo!X:Y,2,FALSE),"") -> 23260 | N7: =IFERROR(VLOOKUP(B7,Petróleo!Z:AA,2,FALSE),"") -> 5360 | O7: =IFERROR(VLOOKUP(B7,Petróleo!AB:AC,2,FALSE),"") -> 1950 | P7: =IFERROR(VLOOKUP(B7,Petróleo!AD:AE,2,FALSE),"") -> 2930 | Q7: =IFERROR(VLOOKUP(B7,Petróleo!AF:AG,2,FALSE),"") -> 3150 | R7: =IFERROR(VLOOKUP(B7,Petróleo!AH:AI,2,FALSE),"") -> 1300 | S7: =IFERROR(VLOOKUP(B7,Petróleo!AJ:AK,2,FALSE),"") -> 1760 | T7: =IFERROR(VLOOKUP(B7,Petróleo!AL:AM,2,FALSE),"") -> 2000 | U7: =IFERROR(VLOOKUP(B7,Petróleo!AN:AO,2,FALSE),"") -> 1860 | V7: =IFERROR(VLOOKUP(A7,Petróleo!AR:AT,3,FALSE),"") | X7: Doe_nig_prod
A8: =MONTH(B8)&YEAR(B8) -> 71990 | B8: 33085 | C8: =IFERROR(VLOOKUP(B8,Petróleo!A:B,2,FALSE),"") -> 7173 | D8: =IFERROR(VLOOKUP(B8,Estoque_US!D:E,2,FALSE),"") -> 3735 | E8: =IFERROR(VLOOKUP(B8,Petróleo!F:G,2,FALSE),"") | F8: =IFERROR(VLOOKUP(B8,Petróleo!H:I,2,FALSE),"") | G8: =IFERROR(VLOOKUP(B8,Petróleo!J:K,2,FALSE),"") | H8: =IFERROR(VLOOKUP(B8,Petróleo!L:M,2,FALSE),"") | I8: =IFERROR(VLOOKUP(B8,Petróleo!N:O,2,FALSE),"") | J8: =IFERROR(VLOOKUP(B8,Petróleo!P:Q,2,FALSE),"") | K8: =IFERROR(VLOOKUP(B8,Petróleo!R:S,2,FALSE),"") | L8: =IFERROR(VLOOKUP(B8,Petróleo!T:U,2,FALSE),"") | M8: =IFERROR(VLOOKUP(B8,Petróleo!X:Y,2,FALSE),"") -> 23410 | N8: =IFERROR(VLOOKUP(B8,Petróleo!Z:AA,2,FALSE),"") -> 5375 | O8: =IFERROR(VLOOKUP(B8,Petróleo!AB:AC,2,FALSE),"") -> 1970 | P8: =IFERROR(VLOOKUP(B8,Petróleo!AD:AE,2,FALSE),"") -> 2910 | Q8: =IFERROR(VLOOKUP(B8,Petróleo!AF:AG,2,FALSE),"") -> 3280 | R8: =IFERROR(VLOOKUP(B8,Petróleo!AH:AI,2,FALSE),"") -> 1300 | S8: =IFERROR(VLOOKUP(B8,Petróleo!AJ:AK,2,FALSE),"") -> 1750 | T8: =IFERROR(VLOOKUP(B8,Petróleo!AL:AM,2,FALSE),"") -> 2000 | U8: =IFERROR(VLOOKUP(B8,Petróleo!AN:AO,2,FALSE),"") -> 1875 | V8: =IFERROR(VLOOKUP(A8,Petróleo!AR:AT,3,FALSE),"") | X8: rus_prod
A9: =MONTH(B9)&YEAR(B9) -> 81990 | B9: 33116 | C9: =IFERROR(VLOOKUP(B9,Petróleo!A:B,2,FALSE),"") -> 7287 | D9: =IFERROR(VLOOKUP(B9,Estoque_US!D:E,2,FALSE),"") -> -16027 | E9: =IFERROR(VLOOKUP(B9,Petróleo!F:G,2,FALSE),"") | F9: =IFERROR(VLOOKUP(B9,Petróleo!H:I,2,FALSE),"") | G9: =IFERROR(VLOOKUP(B9,Petróleo!J:K,2,FALSE),"") | H9: =IFERROR(VLOOKUP(B9,Petróleo!L:M,2,FALSE),"") | I9: =IFERROR(VLOOKUP(B9,Petróleo!N:O,2,FALSE),"") | J9: =IFERROR(VLOOKUP(B9,Petróleo!P:Q,2,FALSE),"") | K9: =IFERROR(VLOOKUP(B9,Petróleo!R:S,2,FALSE),"") | L9: =IFERROR(VLOOKUP(B9,Petróleo!T:U,2,FALSE),"") | M9: =IFERROR(VLOOKUP(B9,Petróleo!X:Y,2,FALSE),"") -> 19580 | N9: =IFERROR(VLOOKUP(B9,Petróleo!Z:AA,2,FALSE),"") -> 5630 | O9: =IFERROR(VLOOKUP(B9,Petróleo!AB:AC,2,FALSE),"") -> 1600 | P9: =IFERROR(VLOOKUP(B9,Petróleo!AD:AE,2,FALSE),"") -> 3200 | Q9: =IFERROR(VLOOKUP(B9,Petróleo!AF:AG,2,FALSE),"") -> 700 | R9: =IFERROR(VLOOKUP(B9,Petróleo!AH:AI,2,FALSE),"") -> 1350 | S9: =IFERROR(VLOOKUP(B9,Petróleo!AJ:AK,2,FALSE),"") -> 1800 | T9: =IFERROR(VLOOKUP(B9,Petróleo!AL:AM,2,FALSE),"") -> 2000 | U9: =IFERROR(VLOOKUP(B9,Petróleo!AN:AO,2,FALSE),"") -> 280 | V9: =IFERROR(VLOOKUP(A9,Petróleo!AR:AT,3,FALSE),"") | X9: Doe_Ven_prod
A10: =MONTH(B10)&YEAR(B10) -> 91990 | B10: 33146 | C10: =IFERROR(VLOOKUP(B10,Petróleo!A:B,2,FALSE),"") -> 7224 | D10: =IFERROR(VLOOKUP(B10,Estoque_US!D:E,2,FALSE),"") -> -18310 | E10: =IFERROR(VLOOKUP(B10,Petróleo!F:G,2,FALSE),"") | F10: =IFERROR(VLOOKUP(B10,Petróleo!H:I,2,FALSE),"") | G10: =IFERROR(VLOOKUP(B10,Petróleo!J:K,2,FALSE),"") | H10: =IFERROR(VLOOKUP(B10,Petróleo!L:M,2,FALSE),"") | I10: =IFERROR(VLOOKUP(B10,Petróleo!N:O,2,FALSE),"") | J10: =IFERROR(VLOOKUP(B10,Petróleo!P:Q,2,FALSE),"") | K10: =IFERROR(VLOOKUP(B10,Petróleo!R:S,2,FALSE),"") | L10: =IFERROR(VLOOKUP(B10,Petróleo!T:U,2,FALSE),"") | M10: =IFERROR(VLOOKUP(B10,Petróleo!X:Y,2,FALSE),"") -> 22685 | N10: =IFERROR(VLOOKUP(B10,Petróleo!Z:AA,2,FALSE),"") -> 7630 | O10: =IFERROR(VLOOKUP(B10,Petróleo!AB:AC,2,FALSE),"") -> 2215 | P10: =IFERROR(VLOOKUP(B10,Petróleo!AD:AE,2,FALSE),"") -> 3470 | Q10: =IFERROR(VLOOKUP(B10,Petróleo!AF:AG,2,FALSE),"") -> 450 | R10: =IFERROR(VLOOKUP(B10,Petróleo!AH:AI,2,FALSE),"") -> 1430 | S10: =IFERROR(VLOOKUP(B10,Petróleo!AJ:AK,2,FALSE),"") -> 1870 | T10: =IFERROR(VLOOKUP(B10,Petróleo!AL:AM,2,FALSE),"") -> 2250 | U10: =IFERROR(VLOOKUP(B10,Petróleo!AN:AO,2,FALSE),"") -> 230 | V10: =IFERROR(VLOOKUP(A10,Petróleo!AR:AT,3,FALSE),"") | X10: Doe_chi_prod
A11: =MONTH(B11)&YEAR(B11) -> 101990 | B11: 33177 | C11: =IFERROR(VLOOKUP(B11,Petróleo!A:B,2,FALSE),"") -> 7542 | D11: =IFERROR(VLOOKUP(B11,Estoque_US!D:E,2,FALSE),"") -> -11229 | E11: =IFERROR(VLOOKUP(B11,Petróleo!F:G,2,FALSE),"") | F11: =IFERROR(VLOOKUP(B11,Petróleo!H:I,2,FALSE),"") | G11: =IFERROR(VLOOKUP(B11,Petróleo!J:K,2,FALSE),"") | H11: =IFERROR(VLOOKUP(B11,Petróleo!L:M,2,FALSE),"") | I11: =IFERROR(VLOOKUP(B11,Petróleo!N:O,2,FALSE),"") | J11: =IFERROR(VLOOKUP(B11,Petróleo!P:Q,2,FALSE),"") | K11: =IFERROR(VLOOKUP(B11,Petróleo!R:S,2,FALSE),"") | L11: =IFERROR(VLOOKUP(B11,Petróleo!T:U,2,FALSE),"") | M11: =IFERROR(VLOOKUP(B11,Petróleo!X:Y,2,FALSE),"") -> 22660 | N11: =IFERROR(VLOOKUP(B11,Petróleo!Z:AA,2,FALSE),"") -> 7800 | O11: =IFERROR(VLOOKUP(B11,Petróleo!AB:AC,2,FALSE),"") -> 2240 | P11: =IFERROR(VLOOKUP(B11,Petróleo!AD:AE,2,FALSE),"") -> 3000 | Q11: =IFERROR(VLOOKUP(B11,Petróleo!AF:AG,2,FALSE),"") -> 450 | R11: =IFERROR(VLOOKUP(B11,Petróleo!AH:AI,2,FALSE),"") -> 1600 | S11: =IFERROR(VLOOKUP(B11,Petróleo!AJ:AK,2,FALSE),"") -> 1900 | T11: =IFERROR(VLOOKUP(B11,Petróleo!AL:AM,2,FALSE),"") -> 2300 | U11: =IFERROR(VLOOKUP(B11,Petróleo!AN:AO,2,FALSE),"") -> 230 | V11: =IFERROR(VLOOKUP(A11,Petróleo!AR:AT,3,FALSE),"") | X11: Bbg_opep_prod
A12: =MONTH(B12)&YEAR(B12) -> 111990 | B12: 33207 | C12: =IFERROR(VLOOKUP(B12,Petróleo!A:B,2,FALSE),"") -> 7387 | D12: =IFERROR(VLOOKUP(B12,Estoque_US!D:E,2,FALSE),"") -> -488 | E12: =IFERROR(VLOOKUP(B12,Petróleo!F:G,2,FALSE),"") | F12: =IFERROR(VLOOKUP(B12,Petróleo!H:I,2,FALSE),"") | G12: =IFERROR(VLOOKUP(B12,Petróleo!J:K,2,FALSE),"") | H12: =IFERROR(VLOOKUP(B12,Petróleo!L:M,2,FALSE),"") | I12: =IFERROR(VLOOKUP(B12,Petróleo!N:O,2,FALSE),"") | J12: =IFERROR(VLOOKUP(B12,Petróleo!P:Q,2,FALSE),"") | K12: =IFERROR(VLOOKUP(B12,Petróleo!R:S,2,FALSE),"") | L12: =IFERROR(VLOOKUP(B12,Petróleo!T:U,2,FALSE),"") | M12: =IFERROR(VLOOKUP(B12,Petróleo!X:Y,2,FALSE),"") -> 23630 | N12: =IFERROR(VLOOKUP(B12,Petróleo!Z:AA,2,FALSE),"") -> 8330 | O12: =IFERROR(VLOOKUP(B12,Petróleo!AB:AC,2,FALSE),"") -> 2300 | P12: =IFERROR(VLOOKUP(B12,Petróleo!AD:AE,2,FALSE),"") -> 3460 | Q12: =IFERROR(VLOOKUP(B12,Petróleo!AF:AG,2,FALSE),"") -> 450 | R12: =IFERROR(VLOOKUP(B12,Petróleo!AH:AI,2,FALSE),"") -> 1550 | S12: =IFERROR(VLOOKUP(B12,Petróleo!AJ:AK,2,FALSE),"") -> 1900 | T12: =IFERROR(VLOOKUP(B12,Petróleo!AL:AM,2,FALSE),"") -> 2300 | U12: =IFERROR(VLOOKUP(B12,Petróleo!AN:AO,2,FALSE),"") -> 230 | V12: =IFERROR(VLOOKUP(A12,Petróleo!AR:AT,3,FALSE),"") | X12: Bbg_SA_prod
A13: =MONTH(B13)&YEAR(B13) -> 121990 | B13: 33238 | C13: =IFERROR(VLOOKUP(B13,Petróleo!A:B,2,FALSE),"") -> 7338 | D13: =IFERROR(VLOOKUP(B13,Estoque_US!D:E,2,FALSE),"") -> -10990 | E13: =IFERROR(VLOOKUP(B13,Petróleo!F:G,2,FALSE),"") | F13: =IFERROR(VLOOKUP(B13,Petróleo!H:I,2,FALSE),"") | G13: =IFERROR(VLOOKUP(B13,Petróleo!J:K,2,FALSE),"") | H13: =IFERROR(VLOOKUP(B13,Petróleo!L:M,2,FALSE),"") | I13: =IFERROR(VLOOKUP(B13,Petróleo!N:O,2,FALSE),"") | J13: =IFERROR(VLOOKUP(B13,Petróleo!P:Q,2,FALSE),"") | K13: =IFERROR(VLOOKUP(B13,Petróleo!R:S,2,FALSE),"") | L13: =IFERROR(VLOOKUP(B13,Petróleo!T:U,2,FALSE),"") | M13: =IFERROR(VLOOKUP(B13,Petróleo!X:Y,2,FALSE),"") -> 23860 | N13: =IFERROR(VLOOKUP(B13,Petróleo!Z:AA,2,FALSE),"") -> 8430 | O13: =IFERROR(VLOOKUP(B13,Petróleo!AB:AC,2,FALSE),"") -> 2350 | P13: =IFERROR(VLOOKUP(B13,Petróleo!AD:AE,2,FALSE),"") -> 3450 | Q13: =IFERROR(VLOOKUP(B13,Petróleo!AF:AG,2,FALSE),"") -> 450 | R13: =IFERROR(VLOOKUP(B13,Petróleo!AH:AI,2,FALSE),"") -> 1550 | S13: =IFERROR(VLOOKUP(B13,Petróleo!AJ:AK,2,FALSE),"") -> 1900 | T13: =IFERROR(VLOOKUP(B13,Petróleo!AL:AM,2,FALSE),"") -> 2350 | U13: =IFERROR(VLOOKUP(B13,Petróleo!AN:AO,2,FALSE),"") -> 230 | V13: =IFERROR(VLOOKUP(A13,Petróleo!AR:AT,3,FALSE),"") | X13: Bbg_Ae_prod
A14: =MONTH(B14)&YEAR(B14) -> 11991 | B14: 33269 | C14: =IFERROR(VLOOKUP(B14,Petróleo!A:B,2,FALSE),"") -> 7500 | D14: =IFERROR(VLOOKUP(B14,Estoque_US!D:E,2,FALSE),"") -> -8112 | E14: =IFERROR(VLOOKUP(B14,Petróleo!F:G,2,FALSE),"") | F14: =IFERROR(VLOOKUP(B14,Petróleo!H:I,2,FALSE),"") | G14: =IFERROR(VLOOKUP(B14,Petróleo!J:K,2,FALSE),"") | H14: =IFERROR(VLOOKUP(B14,Petróleo!L:M,2,FALSE),"") | I14: =IFERROR(VLOOKUP(B14,Petróleo!N:O,2,FALSE),"") | J14: =IFERROR(VLOOKUP(B14,Petróleo!P:Q,2,FALSE),"") | K14: =IFERROR(VLOOKUP(B14,Petróleo!R:S,2,FALSE),"") | L14: =IFERROR(VLOOKUP(B14,Petróleo!T:U,2,FALSE),"") | M14: =IFERROR(VLOOKUP(B14,Petróleo!X:Y,2,FALSE),"") -> 22950 | N14: =IFERROR(VLOOKUP(B14,Petróleo!Z:AA,2,FALSE),"") -> 8000 | O14: =IFERROR(VLOOKUP(B14,Petróleo!AB:AC,2,FALSE),"") -> 2350 | P14: =IFERROR(VLOOKUP(B14,Petróleo!AD:AE,2,FALSE),"") -> 3100 | Q14: =IFERROR(VLOOKUP(B14,Petróleo!AF:AG,2,FALSE),"") -> 350 | R14: =IFERROR(VLOOKUP(B14,Petróleo!AH:AI,2,FALSE),"") -> 1500 | S14: =IFERROR(VLOOKUP(B14,Petróleo!AJ:AK,2,FALSE),"") -> 1900 | T14: =IFERROR(VLOOKUP(B14,Petróleo!AL:AM,2,FALSE),"") -> 2350 | U14: =IFERROR(VLOOKUP(B14,Petróleo!AN:AO,2,FALSE),"") -> 150 | V14: =IFERROR(VLOOKUP(A14,Petróleo!AR:AT,3,FALSE),"") | X14: Bbg_ira_prod
... A20: =MONTH(B20)&YEAR(B20) -> 71991 | B20: 33450 | C20: =IFERROR(VLOOKUP(B20,Petróleo!A:B,2,FALSE),"") -> 7347 | D20: =IFERROR(VLOOKUP(B20,Estoque_US!D:E,2,FALSE),"") -> -5330 | E20: =IFERROR(VLOOKUP(B20,Petróleo!F:G,2,FALSE),"") | F20: =IFERROR(VLOOKUP(B20,Petróleo!H:I,2,FALSE),"") | G20: =IFERROR(VLOOKUP(B20,Petróleo!J:K,2,FALSE),"") | H20: =IFERROR(VLOOKUP(B20,Petróleo!L:M,2,FALSE),"") | I20: =IFERROR(VLOOKUP(B20,Petróleo!N:O,2,FALSE),"") | J20: =IFERROR(VLOOKUP(B20,Petróleo!P:Q,2,FALSE),"") | K20: =IFERROR(VLOOKUP(B20,Petróleo!R:S,2,FALSE),"") | L20: =IFERROR(VLOOKUP(B20,Petróleo!T:U,2,FALSE),"") | M20: =IFERROR(VLOOKUP(B20,Petróleo!X:Y,2,FALSE),"") -> 23190 | N20: =IFERROR(VLOOKUP(B20,Petróleo!Z:AA,2,FALSE),"") -> 8225 | O20: =IFERROR(VLOOKUP(B20,Petróleo!AB:AC,2,FALSE),"") -> 2350 | P20: =IFERROR(VLOOKUP(B20,Petróleo!AD:AE,2,FALSE),"") -> 3300 | Q20: =IFERROR(VLOOKUP(B20,Petróleo!AF:AG,2,FALSE),"") -> 350 | R20: =IFERROR(VLOOKUP(B20,Petróleo!AH:AI,2,FALSE),"") -> 1450 | S20: =IFERROR(VLOOKUP(B20,Petróleo!AJ:AK,2,FALSE),"") -> 1900 | T20: =IFERROR(VLOOKUP(B20,Petróleo!AL:AM,2,FALSE),"") -> 2350 | U20: =IFERROR(VLOOKUP(B20,Petróleo!AN:AO,2,FALSE),"") -> 85 | V20: =IFERROR(VLOOKUP(A20,Petróleo!AR:AT,3,FALSE),"") | X20: P_brent
A21: =MONTH(B21)&YEAR(B21) -> 81991 | B21: 33481 | C21: =IFERROR(VLOOKUP(B21,Petróleo!A:B,2,FALSE),"") -> 7316 | D21: =IFERROR(VLOOKUP(B21,Estoque_US!D:E,2,FALSE),"") -> 7663 | E21: =IFERROR(VLOOKUP(B21,Petróleo!F:G,2,FALSE),"") | F21: =IFERROR(VLOOKUP(B21,Petróleo!H:I,2,FALSE),"") | G21: =IFERROR(VLOOKUP(B21,Petróleo!J:K,2,FALSE),"") | H21: =IFERROR(VLOOKUP(B21,Petróleo!L:M,2,FALSE),"") | I21: =IFERROR(VLOOKUP(B21,Petróleo!N:O,2,FALSE),"") | J21: =IFERROR(VLOOKUP(B21,Petróleo!P:Q,2,FALSE),"") | K21: =IFERROR(VLOOKUP(B21,Petróleo!R:S,2,FALSE),"") | L21: =IFERROR(VLOOKUP(B21,Petróleo!T:U,2,FALSE),"") | M21: =IFERROR(VLOOKUP(B21,Petróleo!X:Y,2,FALSE),"") -> 23430 | N21: =IFERROR(VLOOKUP(B21,Petróleo!Z:AA,2,FALSE),"") -> 8375 | O21: =IFERROR(VLOOKUP(B21,Petróleo!AB:AC,2,FALSE),"") -> 2300 | P21: =IFERROR(VLOOKUP(B21,Petróleo!AD:AE,2,FALSE),"") -> 3300 | Q21: =IFERROR(VLOOKUP(B21,Petróleo!AF:AG,2,FALSE),"") -> 350 | R21: =IFERROR(VLOOKUP(B21,Petróleo!AH:AI,2,FALSE),"") -> 1470 | S21: =IFERROR(VLOOKUP(B21,Petróleo!AJ:AK,2,FALSE),"") -> 1900 | T21: =IFERROR(VLOOKUP(B21,Petróleo!AL:AM,2,FALSE),"") -> 2350 | U21: =IFERROR(VLOOKUP(B21,Petróleo!AN:AO,2,FALSE),"") -> 155 | V21: =IFERROR(VLOOKUP(A21,Petróleo!AR:AT,3,FALSE),"")
A22: =MONTH(B22)&YEAR(B22) -> 91991 | B22: 33511 | C22: =IFERROR(VLOOKUP(B22,Petróleo!A:B,2,FALSE),"") -> 7368 | D22: =IFERROR(VLOOKUP(B22,Estoque_US!D:E,2,FALSE),"") -> -11337 | E22: =IFERROR(VLOOKUP(B22,Petróleo!F:G,2,FALSE),"") | F22: =IFERROR(VLOOKUP(B22,Petróleo!H:I,2,FALSE),"") | G22: =IFERROR(VLOOKUP(B22,Petróleo!J:K,2,FALSE),"") | H22: =IFERROR(VLOOKUP(B22,Petróleo!L:M,2,FALSE),"") | I22: =IFERROR(VLOOKUP(B22,Petróleo!N:O,2,FALSE),"") | J22: =IFERROR(VLOOKUP(B22,Petróleo!P:Q,2,FALSE),"") | K22: =IFERROR(VLOOKUP(B22,Petróleo!R:S,2,FALSE),"") | L22: =IFERROR(VLOOKUP(B22,Petróleo!T:U,2,FALSE),"") | M22: =IFERROR(VLOOKUP(B22,Petróleo!X:Y,2,FALSE),"") -> 23490 | N22: =IFERROR(VLOOKUP(B22,Petróleo!Z:AA,2,FALSE),"") -> 8300 | O22: =IFERROR(VLOOKUP(B22,Petróleo!AB:AC,2,FALSE),"") -> 2330 | P22: =IFERROR(VLOOKUP(B22,Petróleo!AD:AE,2,FALSE),"") -> 3350 | Q22: =IFERROR(VLOOKUP(B22,Petróleo!AF:AG,2,FALSE),"") -> 400 | R22: =IFERROR(VLOOKUP(B22,Petróleo!AH:AI,2,FALSE),"") -> 1450 | S22: =IFERROR(VLOOKUP(B22,Petróleo!AJ:AK,2,FALSE),"") -> 1900 | T22: =IFERROR(VLOOKUP(B22,Petróleo!AL:AM,2,FALSE),"") -> 2350 | U22: =IFERROR(VLOOKUP(B22,Petróleo!AN:AO,2,FALSE),"") -> 160 | V22: =IFERROR(VLOOKUP(A22,Petróleo!AR:AT,3,FALSE),"")
A23: =MONTH(B23)&YEAR(B23) -> 101991 | B23: 33542 | C23: =IFERROR(VLOOKUP(B23,Petróleo!A:B,2,FALSE),"") -> 7437 | D23: =IFERROR(VLOOKUP(B23,Estoque_US!D:E,2,FALSE),"") -> 8273 | E23: =IFERROR(VLOOKUP(B23,Petróleo!F:G,2,FALSE),"") | F23: =IFERROR(VLOOKUP(B23,Petróleo!H:I,2,FALSE),"") | G23: =IFERROR(VLOOKUP(B23,Petróleo!J:K,2,FALSE),"") | H23: =IFERROR(VLOOKUP(B23,Petróleo!L:M,2,FALSE),"") | I23: =IFERROR(VLOOKUP(B23,Petróleo!N:O,2,FALSE),"") | J23: =IFERROR(VLOOKUP(B23,Petróleo!P:Q,2,FALSE),"") | K23: =IFERROR(VLOOKUP(B23,Petróleo!R:S,2,FALSE),"") | L23: =IFERROR(VLOOKUP(B23,Petróleo!T:U,2,FALSE),"") | M23: =IFERROR(VLOOKUP(B23,Petróleo!X:Y,2,FALSE),"") -> 23490 | N23: =IFERROR(VLOOKUP(B23,Petróleo!Z:AA,2,FALSE),"") -> 8350 | O23: =IFERROR(VLOOKUP(B23,Petróleo!AB:AC,2,FALSE),"") -> 2450 | P23: =IFERROR(VLOOKUP(B23,Petróleo!AD:AE,2,FALSE),"") -> 3200 | Q23: =IFERROR(VLOOKUP(B23,Petróleo!AF:AG,2,FALSE),"") -> 450 | R23: =IFERROR(VLOOKUP(B23,Petróleo!AH:AI,2,FALSE),"") -> 1450 | S23: =IFERROR(VLOOKUP(B23,Petróleo!AJ:AK,2,FALSE),"") -> 1800 | T23: =IFERROR(VLOOKUP(B23,Petróleo!AL:AM,2,FALSE),"") -> 2350 | U23: =IFERROR(VLOOKUP(B23,Petróleo!AN:AO,2,FALSE),"") -> 270 | V23: =IFERROR(VLOOKUP(A23,Petróleo!AR:AT,3,FALSE),"")
A24: =MONTH(B24)&YEAR(B24) -> 111991 | B24: 33572 | C24: =IFERROR(VLOOKUP(B24,Petróleo!A:B,2,FALSE),"") -> 7328 | D24: =IFERROR(VLOOKUP(B24,Estoque_US!D:E,2,FALSE),"") -> -8592 | E24: =IFERROR(VLOOKUP(B24,Petróleo!F:G,2,FALSE),"") | F24: =IFERROR(VLOOKUP(B24,Petróleo!H:I,2,FALSE),"") | G24: =IFERROR(VLOOKUP(B24,Petróleo!J:K,2,FALSE),"") | H24: =IFERROR(VLOOKUP(B24,Petróleo!L:M,2,FALSE),"") | I24: =IFERROR(VLOOKUP(B24,Petróleo!N:O,2,FALSE),"") | J24: =IFERROR(VLOOKUP(B24,Petróleo!P:Q,2,FALSE),"") | K24: =IFERROR(VLOOKUP(B24,Petróleo!R:S,2,FALSE),"") | L24: =IFERROR(VLOOKUP(B24,Petróleo!T:U,2,FALSE),"") | M24: =IFERROR(VLOOKUP(B24,Petróleo!X:Y,2,FALSE),"") -> 23850 | N24: =IFERROR(VLOOKUP(B24,Petróleo!Z:AA,2,FALSE),"") -> 8360 | O24: =IFERROR(VLOOKUP(B24,Petróleo!AB:AC,2,FALSE),"") -> 2470 | P24: =IFERROR(VLOOKUP(B24,Petróleo!AD:AE,2,FALSE),"") -> 3300 | Q24: =IFERROR(VLOOKUP(B24,Petróleo!AF:AG,2,FALSE),"") -> 450 | R24: =IFERROR(VLOOKUP(B24,Petróleo!AH:AI,2,FALSE),"") -> 1550 | S24: =IFERROR(VLOOKUP(B24,Petróleo!AJ:AK,2,FALSE),"") -> 1850 | T24: =IFERROR(VLOOKUP(B24,Petróleo!AL:AM,2,FALSE),"") -> 2350 | U24: =IFERROR(VLOOKUP(B24,Petróleo!AN:AO,2,FALSE),"") -> 330 | V24: =IFERROR(VLOOKUP(A24,Petróleo!AR:AT,3,FALSE),"")
A25: =MONTH(B25)&YEAR(B25) -> 121991 | B25: 33603 | C25: =IFERROR(VLOOKUP(B25,Petróleo!A:B,2,FALSE),"") -> 7299 | D25: =IFERROR(VLOOKUP(B25,Estoque_US!D:E,2,FALSE),"") -> -14696 | E25: =IFERROR(VLOOKUP(B25,Petróleo!F:G,2,FALSE),"") | F25: =IFERROR(VLOOKUP(B25,Petróleo!H:I,2,FALSE),"") | G25: =IFERROR(VLOOKUP(B25,Petróleo!J:K,2,FALSE),"") | H25: =IFERROR(VLOOKUP(B25,Petróleo!L:M,2,FALSE),"") | I25: =IFERROR(VLOOKUP(B25,Petróleo!N:O,2,FALSE),"") | J25: =IFERROR(VLOOKUP(B25,Petróleo!P:Q,2,FALSE),"") | K25: =IFERROR(VLOOKUP(B25,Petróleo!R:S,2,FALSE),"") | L25: =IFERROR(VLOOKUP(B25,Petróleo!T:U,2,FALSE),"") | M25: =IFERROR(VLOOKUP(B25,Petróleo!X:Y,2,FALSE),"") -> 24350 | N25: =IFERROR(VLOOKUP(B25,Petróleo!Z:AA,2,FALSE),"") -> 8500 | O25: =IFERROR(VLOOKUP(B25,Petróleo!AB:AC,2,FALSE),"") -> 2450 | P25: =IFERROR(VLOOKUP(B25,Petróleo!AD:AE,2,FALSE),"") -> 3350 | Q25: =IFERROR(VLOOKUP(B25,Petróleo!AF:AG,2,FALSE),"") -> 480 | R25: =IFERROR(VLOOKUP(B25,Petróleo!AH:AI,2,FALSE),"") -> 1600 | S25: =IFERROR(VLOOKUP(B25,Petróleo!AJ:AK,2,FALSE),"") -> 1930 | T25: =IFERROR(VLOOKUP(B25,Petróleo!AL:AM,2,FALSE),"") -> 2350 | U25: =IFERROR(VLOOKUP(B25,Petróleo!AN:AO,2,FALSE),"") -> 520 | V25: =IFERROR(VLOOKUP(A25,Petróleo!AR:AT,3,FALSE),"")
A26: =MONTH(B26)&YEAR(B26) -> 11992 | B26: 33634 | C26: =IFERROR(VLOOKUP(B26,Petróleo!A:B,2,FALSE),"") -> 7361 | D26: =IFERROR(VLOOKUP(B26,Estoque_US!D:E,2,FALSE),"") -> 9041 | E26: =IFERROR(VLOOKUP(B26,Petróleo!F:G,2,FALSE),"") | F26: =IFERROR(VLOOKUP(B26,Petróleo!H:I,2,FALSE),"") | G26: =IFERROR(VLOOKUP(B26,Petróleo!J:K,2,FALSE),"") | H26: =IFERROR(VLOOKUP(B26,Petróleo!L:M,2,FALSE),"") | I26: =IFERROR(VLOOKUP(B26,Petróleo!N:O,2,FALSE),"") | J26: =IFERROR(VLOOKUP(B26,Petróleo!P:Q,2,FALSE),"") | K26: =IFERROR(VLOOKUP(B26,Petróleo!R:S,2,FALSE),"") | L26: =IFERROR(VLOOKUP(B26,Petróleo!T:U,2,FALSE),"") | M26: =IFERROR(VLOOKUP(B26,Petróleo!X:Y,2,FALSE),"") -> 24340 | N26: =IFERROR(VLOOKUP(B26,Petróleo!Z:AA,2,FALSE),"") -> 8650 | O26: =IFERROR(VLOOKUP(B26,Petróleo!AB:AC,2,FALSE),"") -> 2390 | P26: =IFERROR(VLOOKUP(B26,Petróleo!AD:AE,2,FALSE),"") -> 3390 | Q26: =IFERROR(VLOOKUP(B26,Petróleo!AF:AG,2,FALSE),"") -> 480 | R26: =IFERROR(VLOOKUP(B26,Petróleo!AH:AI,2,FALSE),"") -> 1570 | S26: =IFERROR(VLOOKUP(B26,Petróleo!AJ:AK,2,FALSE),"") -> 1900 | T26: =IFERROR(VLOOKUP(B26,Petróleo!AL:AM,2,FALSE),"") -> 2300 | U26: =IFERROR(VLOOKUP(B26,Petróleo!AN:AO,2,FALSE),"") -> 560 | V26: =IFERROR(VLOOKUP(A26,Petróleo!AR:AT,3,FALSE),"")
A27: =MONTH(B27)&YEAR(B27) -> 21992 | B27: 33663 | C27: =IFERROR(VLOOKUP(B27,Petróleo!A:B,2,FALSE),"") -> 7389 | D27: =IFERROR(VLOOKUP(B27,Estoque_US!D:E,2,FALSE),"") -> 8189 | E27: =IFERROR(VLOOKUP(B27,Petróleo!F:G,2,FALSE),"") | F27: =IFERROR(VLOOKUP(B27,Petróleo!H:I,2,FALSE),"") | G27: =IFERROR(VLOOKUP(B27,Petróleo!J:K,2,FALSE),"") | H27: =IFERROR(VLOOKUP(B27,Petróleo!L:M,2,FALSE),"") | I27: =IFERROR(VLOOKUP(B27,Petróleo!N:O,2,FALSE),"") | J27: =IFERROR(VLOOKUP(B27,Petróleo!P:Q,2,FALSE),"") | K27: =IFERROR(VLOOKUP(B27,Petróleo!R:S,2,FALSE),"") | L27: =IFERROR(VLOOKUP(B27,Petróleo!T:U,2,FALSE),"") | M27: =IFERROR(VLOOKUP(B27,Petróleo!X:Y,2,FALSE),"") -> 23940 | N27: =IFERROR(VLOOKUP(B27,Petróleo!Z:AA,2,FALSE),"") -> 8450 | O27: =IFERROR(VLOOKUP(B27,Petróleo!AB:AC,2,FALSE),"") -> 2340 | P27: =IFERROR(VLOOKUP(B27,Petróleo!AD:AE,2,FALSE),"") -> 3350 | Q27: =IFERROR(VLOOKUP(B27,Petróleo!AF:AG,2,FALSE),"") -> 480 | R27: =IFERROR(VLOOKUP(B27,Petróleo!AH:AI,2,FALSE),"") -> 1550 | S27: =IFERROR(VLOOKUP(B27,Petróleo!AJ:AK,2,FALSE),"") -> 1850 | T27: =IFERROR(VLOOKUP(B27,Petróleo!AL:AM,2,FALSE),"") -> 2250 | U27: =IFERROR(VLOOKUP(B27,Petróleo!AN:AO,2,FALSE),"") -> 600 | V27: =IFERROR(VLOOKUP(A27,Petróleo!AR:AT,3,FALSE),"")
A28: =MONTH(B28)&YEAR(B28) -> 31992 | B28: 33694 | C28: =IFERROR(VLOOKUP(B28,Petróleo!A:B,2,FALSE),"") -> 7348 | D28: =IFERROR(VLOOKUP(B28,Estoque_US!D:E,2,FALSE),"") -> -864 | E28: =IFERROR(VLOOKUP(B28,Petróleo!F:G,2,FALSE),"") | F28: =IFERROR(VLOOKUP(B28,Petróleo!H:I,2,FALSE),"") | G28: =IFERROR(VLOOKUP(B28,Petróleo!J:K,2,FALSE),"") | H28: =IFERROR(VLOOKUP(B28,Petróleo!L:M,2,FALSE),"") | I28: =IFERROR(VLOOKUP(B28,Petróleo!N:O,2,FALSE),"") | J28: =IFERROR(VLOOKUP(B28,Petróleo!P:Q,2,FALSE),"") | K28: =IFERROR(VLOOKUP(B28,Petróleo!R:S,2,FALSE),"") | L28: =IFERROR(VLOOKUP(B28,Petróleo!T:U,2,FALSE),"") | M28: =IFERROR(VLOOKUP(B28,Petróleo!X:Y,2,FALSE),"") -> 23370 | N28: =IFERROR(VLOOKUP(B28,Petróleo!Z:AA,2,FALSE),"") -> 8070 | O28: =IFERROR(VLOOKUP(B28,Petróleo!AB:AC,2,FALSE),"") -> 2250 | P28: =IFERROR(VLOOKUP(B28,Petróleo!AD:AE,2,FALSE),"") -> 3350 | Q28: =IFERROR(VLOOKUP(B28,Petróleo!AF:AG,2,FALSE),"") -> 450 | R28: =IFERROR(VLOOKUP(B28,Petróleo!AH:AI,2,FALSE),"") -> 1450 | S28: =IFERROR(VLOOKUP(B28,Petróleo!AJ:AK,2,FALSE),"") -> 1820 | T28: =IFERROR(VLOOKUP(B28,Petróleo!AL:AM,2,FALSE),"") -> 2150 | U28: =IFERROR(VLOOKUP(B28,Petróleo!AN:AO,2,FALSE),"") -> 730 | V28: =IFERROR(VLOOKUP(A28,Petróleo!AR:AT,3,FALSE),"")
A29: =MONTH(B29)&YEAR(B29) -> 41992 | B29: 33724 | C29: =IFERROR(VLOOKUP(B29,Petróleo!A:B,2,FALSE),"") -> 7293 | D29: =IFERROR(VLOOKUP(B29,Estoque_US!D:E,2,FALSE),"") -> 7953 | E29: =IFERROR(VLOOKUP(B29,Petróleo!F:G,2,FALSE),"") | F29: =IFERROR(VLOOKUP(B29,Petróleo!H:I,2,FALSE),"") | G29: =IFERROR(VLOOKUP(B29,Petróleo!J:K,2,FALSE),"") | H29: =IFERROR(VLOOKUP(B29,Petróleo!L:M,2,FALSE),"") | I29: =IFERROR(VLOOKUP(B29,Petróleo!N:O,2,FALSE),"") | J29: =IFERROR(VLOOKUP(B29,Petróleo!P:Q,2,FALSE),"") | K29: =IFERROR(VLOOKUP(B29,Petróleo!R:S,2,FALSE),"") | L29: =IFERROR(VLOOKUP(B29,Petróleo!T:U,2,FALSE),"") | M29: =IFERROR(VLOOKUP(B29,Petróleo!X:Y,2,FALSE),"") -> 23500 | N29: =IFERROR(VLOOKUP(B29,Petróleo!Z:AA,2,FALSE),"") -> 8150 | O29: =IFERROR(VLOOKUP(B29,Petróleo!AB:AC,2,FALSE),"") -> 2230 | P29: =IFERROR(VLOOKUP(B29,Petróleo!AD:AE,2,FALSE),"") -> 3150 | Q29: =IFERROR(VLOOKUP(B29,Petróleo!AF:AG,2,FALSE),"") -> 450 | R29: =IFERROR(VLOOKUP(B29,Petróleo!AH:AI,2,FALSE),"") -> 1500 | S29: =IFERROR(VLOOKUP(B29,Petróleo!AJ:AK,2,FALSE),"") -> 1850 | T29: =IFERROR(VLOOKUP(B29,Petróleo!AL:AM,2,FALSE),"") -> 2180 | U29: =IFERROR(VLOOKUP(B29,Petróleo!AN:AO,2,FALSE),"") -> 850 | V29: =IFERROR(VLOOKUP(A29,Petróleo!AR:AT,3,FALSE),"")
A30: =MONTH(B30)&YEAR(B30) -> 51992 | B30: 33755 | C30: =IFERROR(VLOOKUP(B30,Petróleo!A:B,2,FALSE),"") -> 7169 | D30: =IFERROR(VLOOKUP(B30,Estoque_US!D:E,2,FALSE),"") -> -4636 | E30: =IFERROR(VLOOKUP(B30,Petróleo!F:G,2,FALSE),"") | F30: =IFERROR(VLOOKUP(B30,Petróleo!H:I,2,FALSE),"") | G30: =IFERROR(VLOOKUP(B30,Petróleo!J:K,2,FALSE),"") | H30: =IFERROR(VLOOKUP(B30,Petróleo!L:M,2,FALSE),"") | I30: =IFERROR(VLOOKUP(B30,Petróleo!N:O,2,FALSE),"") | J30: =IFERROR(VLOOKUP(B30,Petróleo!P:Q,2,FALSE),"") | K30: =IFERROR(VLOOKUP(B30,Petróleo!R:S,2,FALSE),"") | L30: =IFERROR(VLOOKUP(B30,Petróleo!T:U,2,FALSE),"") | M30: =IFERROR(VLOOKUP(B30,Petróleo!X:Y,2,FALSE),"") -> 23730 | N30: =IFERROR(VLOOKUP(B30,Petróleo!Z:AA,2,FALSE),"") -> 8200 | O30: =IFERROR(VLOOKUP(B30,Petróleo!AB:AC,2,FALSE),"") -> 2200 | P30: =IFERROR(VLOOKUP(B30,Petróleo!AD:AE,2,FALSE),"") -> 3300 | Q30: =IFERROR(VLOOKUP(B30,Petróleo!AF:AG,2,FALSE),"") -> 450 | R30: =IFERROR(VLOOKUP(B30,Petróleo!AH:AI,2,FALSE),"") -> 1400 | S30: =IFERROR(VLOOKUP(B30,Petróleo!AJ:AK,2,FALSE),"") -> 1800 | T30: =IFERROR(VLOOKUP(B30,Petróleo!AL:AM,2,FALSE),"") -> 2200 | U30: =IFERROR(VLOOKUP(B30,Petróleo!AN:AO,2,FALSE),"") -> 980 | V30: =IFERROR(VLOOKUP(A30,Petróleo!AR:AT,3,FALSE),"")
